ERROR 2016-06-07 18:49:24,584 base.py handle_uncaught_exception 256 Internal Server Error: /admin/login/
Traceback (most recent call last):
  File "/home/guinsly/.pyenv/versions/django1.9.3.4.3/lib/python3.4/site-packages/django/core/handlers/base.py", line 132, in get_response
    response = wrapped_callback(request, *callback_args, **callback_kwargs)
  File "/home/guinsly/.pyenv/versions/django1.9.3.4.3/lib/python3.4/site-packages/django/views/decorators/cache.py", line 57, in _wrapped_view_func
    response = view_func(request, *args, **kwargs)
  File "/home/guinsly/.pyenv/versions/django1.9.3.4.3/lib/python3.4/site-packages/django/contrib/admin/sites.py", line 400, in login
    return login(request, **defaults)
  File "/home/guinsly/.pyenv/versions/django1.9.3.4.3/lib/python3.4/site-packages/django/views/decorators/debug.py", line 76, in sensitive_post_parameters_wrapper
    return view(request, *args, **kwargs)
  File "/home/guinsly/.pyenv/versions/django1.9.3.4.3/lib/python3.4/site-packages/django/utils/decorators.py", line 110, in _wrapped_view
    response = view_func(request, *args, **kwargs)
  File "/home/guinsly/.pyenv/versions/django1.9.3.4.3/lib/python3.4/site-packages/django/views/decorators/cache.py", line 57, in _wrapped_view_func
    response = view_func(request, *args, **kwargs)
  File "/home/guinsly/.pyenv/versions/django1.9.3.4.3/lib/python3.4/site-packages/django/contrib/auth/views.py", line 57, in login
    current_site = get_current_site(request)
  File "/home/guinsly/.pyenv/versions/django1.9.3.4.3/lib/python3.4/site-packages/django/contrib/sites/shortcuts.py", line 15, in get_current_site
    return Site.objects.get_current(request)
  File "/home/guinsly/.pyenv/versions/django1.9.3.4.3/lib/python3.4/site-packages/django/contrib/sites/models.py", line 62, in get_current
    return self._get_site_by_request(request)
  File "/home/guinsly/.pyenv/versions/django1.9.3.4.3/lib/python3.4/site-packages/django/contrib/sites/models.py", line 46, in _get_site_by_request
    site = self.get(domain__iexact=host)
  File "/home/guinsly/.pyenv/versions/django1.9.3.4.3/lib/python3.4/site-packages/django/db/models/manager.py", line 127, in manager_method
    return getattr(self.get_queryset(), name)(*args, **kwargs)
  File "/home/guinsly/.pyenv/versions/django1.9.3.4.3/lib/python3.4/site-packages/django/db/models/query.py", line 334, in get
    self.model._meta.object_name
django.contrib.sites.models.DoesNotExist: Site matching query does not exist.
ERROR 2016-06-07 18:49:24,584 base.py handle_uncaught_exception 256 Internal Server Error: /admin/login/
Traceback (most recent call last):
  File "/home/guinsly/.pyenv/versions/django1.9.3.4.3/lib/python3.4/site-packages/django/core/handlers/base.py", line 132, in get_response
    response = wrapped_callback(request, *callback_args, **callback_kwargs)
  File "/home/guinsly/.pyenv/versions/django1.9.3.4.3/lib/python3.4/site-packages/django/views/decorators/cache.py", line 57, in _wrapped_view_func
    response = view_func(request, *args, **kwargs)
  File "/home/guinsly/.pyenv/versions/django1.9.3.4.3/lib/python3.4/site-packages/django/contrib/admin/sites.py", line 400, in login
    return login(request, **defaults)
  File "/home/guinsly/.pyenv/versions/django1.9.3.4.3/lib/python3.4/site-packages/django/views/decorators/debug.py", line 76, in sensitive_post_parameters_wrapper
    return view(request, *args, **kwargs)
  File "/home/guinsly/.pyenv/versions/django1.9.3.4.3/lib/python3.4/site-packages/django/utils/decorators.py", line 110, in _wrapped_view
    response = view_func(request, *args, **kwargs)
  File "/home/guinsly/.pyenv/versions/django1.9.3.4.3/lib/python3.4/site-packages/django/views/decorators/cache.py", line 57, in _wrapped_view_func
    response = view_func(request, *args, **kwargs)
  File "/home/guinsly/.pyenv/versions/django1.9.3.4.3/lib/python3.4/site-packages/django/contrib/auth/views.py", line 57, in login
    current_site = get_current_site(request)
  File "/home/guinsly/.pyenv/versions/django1.9.3.4.3/lib/python3.4/site-packages/django/contrib/sites/shortcuts.py", line 15, in get_current_site
    return Site.objects.get_current(request)
  File "/home/guinsly/.pyenv/versions/django1.9.3.4.3/lib/python3.4/site-packages/django/contrib/sites/models.py", line 62, in get_current
    return self._get_site_by_request(request)
  File "/home/guinsly/.pyenv/versions/django1.9.3.4.3/lib/python3.4/site-packages/django/contrib/sites/models.py", line 46, in _get_site_by_request
    site = self.get(domain__iexact=host)
  File "/home/guinsly/.pyenv/versions/django1.9.3.4.3/lib/python3.4/site-packages/django/db/models/manager.py", line 127, in manager_method
    return getattr(self.get_queryset(), name)(*args, **kwargs)
  File "/home/guinsly/.pyenv/versions/django1.9.3.4.3/lib/python3.4/site-packages/django/db/models/query.py", line 334, in get
    self.model._meta.object_name
django.contrib.sites.models.DoesNotExist: Site matching query does not exist.
ERROR 2016-06-07 18:49:24,584 base.py handle_uncaught_exception 256 Internal Server Error: /admin/login/
Traceback (most recent call last):
  File "/home/guinsly/.pyenv/versions/django1.9.3.4.3/lib/python3.4/site-packages/django/core/handlers/base.py", line 132, in get_response
    response = wrapped_callback(request, *callback_args, **callback_kwargs)
  File "/home/guinsly/.pyenv/versions/django1.9.3.4.3/lib/python3.4/site-packages/django/views/decorators/cache.py", line 57, in _wrapped_view_func
    response = view_func(request, *args, **kwargs)
  File "/home/guinsly/.pyenv/versions/django1.9.3.4.3/lib/python3.4/site-packages/django/contrib/admin/sites.py", line 400, in login
    return login(request, **defaults)
  File "/home/guinsly/.pyenv/versions/django1.9.3.4.3/lib/python3.4/site-packages/django/views/decorators/debug.py", line 76, in sensitive_post_parameters_wrapper
    return view(request, *args, **kwargs)
  File "/home/guinsly/.pyenv/versions/django1.9.3.4.3/lib/python3.4/site-packages/django/utils/decorators.py", line 110, in _wrapped_view
    response = view_func(request, *args, **kwargs)
  File "/home/guinsly/.pyenv/versions/django1.9.3.4.3/lib/python3.4/site-packages/django/views/decorators/cache.py", line 57, in _wrapped_view_func
    response = view_func(request, *args, **kwargs)
  File "/home/guinsly/.pyenv/versions/django1.9.3.4.3/lib/python3.4/site-packages/django/contrib/auth/views.py", line 57, in login
    current_site = get_current_site(request)
  File "/home/guinsly/.pyenv/versions/django1.9.3.4.3/lib/python3.4/site-packages/django/contrib/sites/shortcuts.py", line 15, in get_current_site
    return Site.objects.get_current(request)
  File "/home/guinsly/.pyenv/versions/django1.9.3.4.3/lib/python3.4/site-packages/django/contrib/sites/models.py", line 62, in get_current
    return self._get_site_by_request(request)
  File "/home/guinsly/.pyenv/versions/django1.9.3.4.3/lib/python3.4/site-packages/django/contrib/sites/models.py", line 46, in _get_site_by_request
    site = self.get(domain__iexact=host)
  File "/home/guinsly/.pyenv/versions/django1.9.3.4.3/lib/python3.4/site-packages/django/db/models/manager.py", line 127, in manager_method
    return getattr(self.get_queryset(), name)(*args, **kwargs)
  File "/home/guinsly/.pyenv/versions/django1.9.3.4.3/lib/python3.4/site-packages/django/db/models/query.py", line 334, in get
    self.model._meta.object_name
django.contrib.sites.models.DoesNotExist: Site matching query does not exist.
ERROR 2016-06-07 18:51:26,638 base.py handle_uncaught_exception 256 Internal Server Error: /admin/login/
Traceback (most recent call last):
  File "/home/guinsly/.pyenv/versions/django1.9.3.4.3/lib/python3.4/site-packages/django/core/handlers/base.py", line 132, in get_response
    response = wrapped_callback(request, *callback_args, **callback_kwargs)
  File "/home/guinsly/.pyenv/versions/django1.9.3.4.3/lib/python3.4/site-packages/django/views/decorators/cache.py", line 57, in _wrapped_view_func
    response = view_func(request, *args, **kwargs)
  File "/home/guinsly/.pyenv/versions/django1.9.3.4.3/lib/python3.4/site-packages/django/contrib/admin/sites.py", line 400, in login
    return login(request, **defaults)
  File "/home/guinsly/.pyenv/versions/django1.9.3.4.3/lib/python3.4/site-packages/django/views/decorators/debug.py", line 76, in sensitive_post_parameters_wrapper
    return view(request, *args, **kwargs)
  File "/home/guinsly/.pyenv/versions/django1.9.3.4.3/lib/python3.4/site-packages/django/utils/decorators.py", line 110, in _wrapped_view
    response = view_func(request, *args, **kwargs)
  File "/home/guinsly/.pyenv/versions/django1.9.3.4.3/lib/python3.4/site-packages/django/views/decorators/cache.py", line 57, in _wrapped_view_func
    response = view_func(request, *args, **kwargs)
  File "/home/guinsly/.pyenv/versions/django1.9.3.4.3/lib/python3.4/site-packages/django/contrib/auth/views.py", line 57, in login
    current_site = get_current_site(request)
  File "/home/guinsly/.pyenv/versions/django1.9.3.4.3/lib/python3.4/site-packages/django/contrib/sites/shortcuts.py", line 15, in get_current_site
    return Site.objects.get_current(request)
  File "/home/guinsly/.pyenv/versions/django1.9.3.4.3/lib/python3.4/site-packages/django/contrib/sites/models.py", line 62, in get_current
    return self._get_site_by_request(request)
  File "/home/guinsly/.pyenv/versions/django1.9.3.4.3/lib/python3.4/site-packages/django/contrib/sites/models.py", line 46, in _get_site_by_request
    site = self.get(domain__iexact=host)
  File "/home/guinsly/.pyenv/versions/django1.9.3.4.3/lib/python3.4/site-packages/django/db/models/manager.py", line 127, in manager_method
    return getattr(self.get_queryset(), name)(*args, **kwargs)
  File "/home/guinsly/.pyenv/versions/django1.9.3.4.3/lib/python3.4/site-packages/django/db/models/query.py", line 334, in get
    self.model._meta.object_name
django.contrib.sites.models.DoesNotExist: Site matching query does not exist.
ERROR 2016-06-07 18:51:26,638 base.py handle_uncaught_exception 256 Internal Server Error: /admin/login/
Traceback (most recent call last):
  File "/home/guinsly/.pyenv/versions/django1.9.3.4.3/lib/python3.4/site-packages/django/core/handlers/base.py", line 132, in get_response
    response = wrapped_callback(request, *callback_args, **callback_kwargs)
  File "/home/guinsly/.pyenv/versions/django1.9.3.4.3/lib/python3.4/site-packages/django/views/decorators/cache.py", line 57, in _wrapped_view_func
    response = view_func(request, *args, **kwargs)
  File "/home/guinsly/.pyenv/versions/django1.9.3.4.3/lib/python3.4/site-packages/django/contrib/admin/sites.py", line 400, in login
    return login(request, **defaults)
  File "/home/guinsly/.pyenv/versions/django1.9.3.4.3/lib/python3.4/site-packages/django/views/decorators/debug.py", line 76, in sensitive_post_parameters_wrapper
    return view(request, *args, **kwargs)
  File "/home/guinsly/.pyenv/versions/django1.9.3.4.3/lib/python3.4/site-packages/django/utils/decorators.py", line 110, in _wrapped_view
    response = view_func(request, *args, **kwargs)
  File "/home/guinsly/.pyenv/versions/django1.9.3.4.3/lib/python3.4/site-packages/django/views/decorators/cache.py", line 57, in _wrapped_view_func
    response = view_func(request, *args, **kwargs)
  File "/home/guinsly/.pyenv/versions/django1.9.3.4.3/lib/python3.4/site-packages/django/contrib/auth/views.py", line 57, in login
    current_site = get_current_site(request)
  File "/home/guinsly/.pyenv/versions/django1.9.3.4.3/lib/python3.4/site-packages/django/contrib/sites/shortcuts.py", line 15, in get_current_site
    return Site.objects.get_current(request)
  File "/home/guinsly/.pyenv/versions/django1.9.3.4.3/lib/python3.4/site-packages/django/contrib/sites/models.py", line 62, in get_current
    return self._get_site_by_request(request)
  File "/home/guinsly/.pyenv/versions/django1.9.3.4.3/lib/python3.4/site-packages/django/contrib/sites/models.py", line 46, in _get_site_by_request
    site = self.get(domain__iexact=host)
  File "/home/guinsly/.pyenv/versions/django1.9.3.4.3/lib/python3.4/site-packages/django/db/models/manager.py", line 127, in manager_method
    return getattr(self.get_queryset(), name)(*args, **kwargs)
  File "/home/guinsly/.pyenv/versions/django1.9.3.4.3/lib/python3.4/site-packages/django/db/models/query.py", line 334, in get
    self.model._meta.object_name
django.contrib.sites.models.DoesNotExist: Site matching query does not exist.
ERROR 2016-06-07 18:51:26,638 base.py handle_uncaught_exception 256 Internal Server Error: /admin/login/
Traceback (most recent call last):
  File "/home/guinsly/.pyenv/versions/django1.9.3.4.3/lib/python3.4/site-packages/django/core/handlers/base.py", line 132, in get_response
    response = wrapped_callback(request, *callback_args, **callback_kwargs)
  File "/home/guinsly/.pyenv/versions/django1.9.3.4.3/lib/python3.4/site-packages/django/views/decorators/cache.py", line 57, in _wrapped_view_func
    response = view_func(request, *args, **kwargs)
  File "/home/guinsly/.pyenv/versions/django1.9.3.4.3/lib/python3.4/site-packages/django/contrib/admin/sites.py", line 400, in login
    return login(request, **defaults)
  File "/home/guinsly/.pyenv/versions/django1.9.3.4.3/lib/python3.4/site-packages/django/views/decorators/debug.py", line 76, in sensitive_post_parameters_wrapper
    return view(request, *args, **kwargs)
  File "/home/guinsly/.pyenv/versions/django1.9.3.4.3/lib/python3.4/site-packages/django/utils/decorators.py", line 110, in _wrapped_view
    response = view_func(request, *args, **kwargs)
  File "/home/guinsly/.pyenv/versions/django1.9.3.4.3/lib/python3.4/site-packages/django/views/decorators/cache.py", line 57, in _wrapped_view_func
    response = view_func(request, *args, **kwargs)
  File "/home/guinsly/.pyenv/versions/django1.9.3.4.3/lib/python3.4/site-packages/django/contrib/auth/views.py", line 57, in login
    current_site = get_current_site(request)
  File "/home/guinsly/.pyenv/versions/django1.9.3.4.3/lib/python3.4/site-packages/django/contrib/sites/shortcuts.py", line 15, in get_current_site
    return Site.objects.get_current(request)
  File "/home/guinsly/.pyenv/versions/django1.9.3.4.3/lib/python3.4/site-packages/django/contrib/sites/models.py", line 62, in get_current
    return self._get_site_by_request(request)
  File "/home/guinsly/.pyenv/versions/django1.9.3.4.3/lib/python3.4/site-packages/django/contrib/sites/models.py", line 46, in _get_site_by_request
    site = self.get(domain__iexact=host)
  File "/home/guinsly/.pyenv/versions/django1.9.3.4.3/lib/python3.4/site-packages/django/db/models/manager.py", line 127, in manager_method
    return getattr(self.get_queryset(), name)(*args, **kwargs)
  File "/home/guinsly/.pyenv/versions/django1.9.3.4.3/lib/python3.4/site-packages/django/db/models/query.py", line 334, in get
    self.model._meta.object_name
django.contrib.sites.models.DoesNotExist: Site matching query does not exist.
ERROR 2016-06-07 18:51:51,996 base.py handle_uncaught_exception 256 Internal Server Error: /admin/login/
Traceback (most recent call last):
  File "/home/guinsly/.pyenv/versions/django1.9.3.4.3/lib/python3.4/site-packages/django/core/handlers/base.py", line 132, in get_response
    response = wrapped_callback(request, *callback_args, **callback_kwargs)
  File "/home/guinsly/.pyenv/versions/django1.9.3.4.3/lib/python3.4/site-packages/django/views/decorators/cache.py", line 57, in _wrapped_view_func
    response = view_func(request, *args, **kwargs)
  File "/home/guinsly/.pyenv/versions/django1.9.3.4.3/lib/python3.4/site-packages/django/contrib/admin/sites.py", line 400, in login
    return login(request, **defaults)
  File "/home/guinsly/.pyenv/versions/django1.9.3.4.3/lib/python3.4/site-packages/django/views/decorators/debug.py", line 76, in sensitive_post_parameters_wrapper
    return view(request, *args, **kwargs)
  File "/home/guinsly/.pyenv/versions/django1.9.3.4.3/lib/python3.4/site-packages/django/utils/decorators.py", line 110, in _wrapped_view
    response = view_func(request, *args, **kwargs)
  File "/home/guinsly/.pyenv/versions/django1.9.3.4.3/lib/python3.4/site-packages/django/views/decorators/cache.py", line 57, in _wrapped_view_func
    response = view_func(request, *args, **kwargs)
  File "/home/guinsly/.pyenv/versions/django1.9.3.4.3/lib/python3.4/site-packages/django/contrib/auth/views.py", line 57, in login
    current_site = get_current_site(request)
  File "/home/guinsly/.pyenv/versions/django1.9.3.4.3/lib/python3.4/site-packages/django/contrib/sites/shortcuts.py", line 15, in get_current_site
    return Site.objects.get_current(request)
  File "/home/guinsly/.pyenv/versions/django1.9.3.4.3/lib/python3.4/site-packages/django/contrib/sites/models.py", line 62, in get_current
    return self._get_site_by_request(request)
  File "/home/guinsly/.pyenv/versions/django1.9.3.4.3/lib/python3.4/site-packages/django/contrib/sites/models.py", line 46, in _get_site_by_request
    site = self.get(domain__iexact=host)
  File "/home/guinsly/.pyenv/versions/django1.9.3.4.3/lib/python3.4/site-packages/django/db/models/manager.py", line 127, in manager_method
    return getattr(self.get_queryset(), name)(*args, **kwargs)
  File "/home/guinsly/.pyenv/versions/django1.9.3.4.3/lib/python3.4/site-packages/django/db/models/query.py", line 334, in get
    self.model._meta.object_name
django.contrib.sites.models.DoesNotExist: Site matching query does not exist.
ERROR 2016-06-07 18:51:51,996 base.py handle_uncaught_exception 256 Internal Server Error: /admin/login/
Traceback (most recent call last):
  File "/home/guinsly/.pyenv/versions/django1.9.3.4.3/lib/python3.4/site-packages/django/core/handlers/base.py", line 132, in get_response
    response = wrapped_callback(request, *callback_args, **callback_kwargs)
  File "/home/guinsly/.pyenv/versions/django1.9.3.4.3/lib/python3.4/site-packages/django/views/decorators/cache.py", line 57, in _wrapped_view_func
    response = view_func(request, *args, **kwargs)
  File "/home/guinsly/.pyenv/versions/django1.9.3.4.3/lib/python3.4/site-packages/django/contrib/admin/sites.py", line 400, in login
    return login(request, **defaults)
  File "/home/guinsly/.pyenv/versions/django1.9.3.4.3/lib/python3.4/site-packages/django/views/decorators/debug.py", line 76, in sensitive_post_parameters_wrapper
    return view(request, *args, **kwargs)
  File "/home/guinsly/.pyenv/versions/django1.9.3.4.3/lib/python3.4/site-packages/django/utils/decorators.py", line 110, in _wrapped_view
    response = view_func(request, *args, **kwargs)
  File "/home/guinsly/.pyenv/versions/django1.9.3.4.3/lib/python3.4/site-packages/django/views/decorators/cache.py", line 57, in _wrapped_view_func
    response = view_func(request, *args, **kwargs)
  File "/home/guinsly/.pyenv/versions/django1.9.3.4.3/lib/python3.4/site-packages/django/contrib/auth/views.py", line 57, in login
    current_site = get_current_site(request)
  File "/home/guinsly/.pyenv/versions/django1.9.3.4.3/lib/python3.4/site-packages/django/contrib/sites/shortcuts.py", line 15, in get_current_site
    return Site.objects.get_current(request)
  File "/home/guinsly/.pyenv/versions/django1.9.3.4.3/lib/python3.4/site-packages/django/contrib/sites/models.py", line 62, in get_current
    return self._get_site_by_request(request)
  File "/home/guinsly/.pyenv/versions/django1.9.3.4.3/lib/python3.4/site-packages/django/contrib/sites/models.py", line 46, in _get_site_by_request
    site = self.get(domain__iexact=host)
  File "/home/guinsly/.pyenv/versions/django1.9.3.4.3/lib/python3.4/site-packages/django/db/models/manager.py", line 127, in manager_method
    return getattr(self.get_queryset(), name)(*args, **kwargs)
  File "/home/guinsly/.pyenv/versions/django1.9.3.4.3/lib/python3.4/site-packages/django/db/models/query.py", line 334, in get
    self.model._meta.object_name
django.contrib.sites.models.DoesNotExist: Site matching query does not exist.
ERROR 2016-06-07 18:51:51,996 base.py handle_uncaught_exception 256 Internal Server Error: /admin/login/
Traceback (most recent call last):
  File "/home/guinsly/.pyenv/versions/django1.9.3.4.3/lib/python3.4/site-packages/django/core/handlers/base.py", line 132, in get_response
    response = wrapped_callback(request, *callback_args, **callback_kwargs)
  File "/home/guinsly/.pyenv/versions/django1.9.3.4.3/lib/python3.4/site-packages/django/views/decorators/cache.py", line 57, in _wrapped_view_func
    response = view_func(request, *args, **kwargs)
  File "/home/guinsly/.pyenv/versions/django1.9.3.4.3/lib/python3.4/site-packages/django/contrib/admin/sites.py", line 400, in login
    return login(request, **defaults)
  File "/home/guinsly/.pyenv/versions/django1.9.3.4.3/lib/python3.4/site-packages/django/views/decorators/debug.py", line 76, in sensitive_post_parameters_wrapper
    return view(request, *args, **kwargs)
  File "/home/guinsly/.pyenv/versions/django1.9.3.4.3/lib/python3.4/site-packages/django/utils/decorators.py", line 110, in _wrapped_view
    response = view_func(request, *args, **kwargs)
  File "/home/guinsly/.pyenv/versions/django1.9.3.4.3/lib/python3.4/site-packages/django/views/decorators/cache.py", line 57, in _wrapped_view_func
    response = view_func(request, *args, **kwargs)
  File "/home/guinsly/.pyenv/versions/django1.9.3.4.3/lib/python3.4/site-packages/django/contrib/auth/views.py", line 57, in login
    current_site = get_current_site(request)
  File "/home/guinsly/.pyenv/versions/django1.9.3.4.3/lib/python3.4/site-packages/django/contrib/sites/shortcuts.py", line 15, in get_current_site
    return Site.objects.get_current(request)
  File "/home/guinsly/.pyenv/versions/django1.9.3.4.3/lib/python3.4/site-packages/django/contrib/sites/models.py", line 62, in get_current
    return self._get_site_by_request(request)
  File "/home/guinsly/.pyenv/versions/django1.9.3.4.3/lib/python3.4/site-packages/django/contrib/sites/models.py", line 46, in _get_site_by_request
    site = self.get(domain__iexact=host)
  File "/home/guinsly/.pyenv/versions/django1.9.3.4.3/lib/python3.4/site-packages/django/db/models/manager.py", line 127, in manager_method
    return getattr(self.get_queryset(), name)(*args, **kwargs)
  File "/home/guinsly/.pyenv/versions/django1.9.3.4.3/lib/python3.4/site-packages/django/db/models/query.py", line 334, in get
    self.model._meta.object_name
django.contrib.sites.models.DoesNotExist: Site matching query does not exist.
ERROR 2016-06-07 18:51:59,166 base.py handle_uncaught_exception 256 Internal Server Error: /admin/login/
Traceback (most recent call last):
  File "/home/guinsly/.pyenv/versions/django1.9.3.4.3/lib/python3.4/site-packages/django/core/handlers/base.py", line 132, in get_response
    response = wrapped_callback(request, *callback_args, **callback_kwargs)
  File "/home/guinsly/.pyenv/versions/django1.9.3.4.3/lib/python3.4/site-packages/django/views/decorators/cache.py", line 57, in _wrapped_view_func
    response = view_func(request, *args, **kwargs)
  File "/home/guinsly/.pyenv/versions/django1.9.3.4.3/lib/python3.4/site-packages/django/contrib/admin/sites.py", line 400, in login
    return login(request, **defaults)
  File "/home/guinsly/.pyenv/versions/django1.9.3.4.3/lib/python3.4/site-packages/django/views/decorators/debug.py", line 76, in sensitive_post_parameters_wrapper
    return view(request, *args, **kwargs)
  File "/home/guinsly/.pyenv/versions/django1.9.3.4.3/lib/python3.4/site-packages/django/utils/decorators.py", line 110, in _wrapped_view
    response = view_func(request, *args, **kwargs)
  File "/home/guinsly/.pyenv/versions/django1.9.3.4.3/lib/python3.4/site-packages/django/views/decorators/cache.py", line 57, in _wrapped_view_func
    response = view_func(request, *args, **kwargs)
  File "/home/guinsly/.pyenv/versions/django1.9.3.4.3/lib/python3.4/site-packages/django/contrib/auth/views.py", line 57, in login
    current_site = get_current_site(request)
  File "/home/guinsly/.pyenv/versions/django1.9.3.4.3/lib/python3.4/site-packages/django/contrib/sites/shortcuts.py", line 15, in get_current_site
    return Site.objects.get_current(request)
  File "/home/guinsly/.pyenv/versions/django1.9.3.4.3/lib/python3.4/site-packages/django/contrib/sites/models.py", line 62, in get_current
    return self._get_site_by_request(request)
  File "/home/guinsly/.pyenv/versions/django1.9.3.4.3/lib/python3.4/site-packages/django/contrib/sites/models.py", line 46, in _get_site_by_request
    site = self.get(domain__iexact=host)
  File "/home/guinsly/.pyenv/versions/django1.9.3.4.3/lib/python3.4/site-packages/django/db/models/manager.py", line 127, in manager_method
    return getattr(self.get_queryset(), name)(*args, **kwargs)
  File "/home/guinsly/.pyenv/versions/django1.9.3.4.3/lib/python3.4/site-packages/django/db/models/query.py", line 334, in get
    self.model._meta.object_name
django.contrib.sites.models.DoesNotExist: Site matching query does not exist.
ERROR 2016-06-07 18:51:59,166 base.py handle_uncaught_exception 256 Internal Server Error: /admin/login/
Traceback (most recent call last):
  File "/home/guinsly/.pyenv/versions/django1.9.3.4.3/lib/python3.4/site-packages/django/core/handlers/base.py", line 132, in get_response
    response = wrapped_callback(request, *callback_args, **callback_kwargs)
  File "/home/guinsly/.pyenv/versions/django1.9.3.4.3/lib/python3.4/site-packages/django/views/decorators/cache.py", line 57, in _wrapped_view_func
    response = view_func(request, *args, **kwargs)
  File "/home/guinsly/.pyenv/versions/django1.9.3.4.3/lib/python3.4/site-packages/django/contrib/admin/sites.py", line 400, in login
    return login(request, **defaults)
  File "/home/guinsly/.pyenv/versions/django1.9.3.4.3/lib/python3.4/site-packages/django/views/decorators/debug.py", line 76, in sensitive_post_parameters_wrapper
    return view(request, *args, **kwargs)
  File "/home/guinsly/.pyenv/versions/django1.9.3.4.3/lib/python3.4/site-packages/django/utils/decorators.py", line 110, in _wrapped_view
    response = view_func(request, *args, **kwargs)
  File "/home/guinsly/.pyenv/versions/django1.9.3.4.3/lib/python3.4/site-packages/django/views/decorators/cache.py", line 57, in _wrapped_view_func
    response = view_func(request, *args, **kwargs)
  File "/home/guinsly/.pyenv/versions/django1.9.3.4.3/lib/python3.4/site-packages/django/contrib/auth/views.py", line 57, in login
    current_site = get_current_site(request)
  File "/home/guinsly/.pyenv/versions/django1.9.3.4.3/lib/python3.4/site-packages/django/contrib/sites/shortcuts.py", line 15, in get_current_site
    return Site.objects.get_current(request)
  File "/home/guinsly/.pyenv/versions/django1.9.3.4.3/lib/python3.4/site-packages/django/contrib/sites/models.py", line 62, in get_current
    return self._get_site_by_request(request)
  File "/home/guinsly/.pyenv/versions/django1.9.3.4.3/lib/python3.4/site-packages/django/contrib/sites/models.py", line 46, in _get_site_by_request
    site = self.get(domain__iexact=host)
  File "/home/guinsly/.pyenv/versions/django1.9.3.4.3/lib/python3.4/site-packages/django/db/models/manager.py", line 127, in manager_method
    return getattr(self.get_queryset(), name)(*args, **kwargs)
  File "/home/guinsly/.pyenv/versions/django1.9.3.4.3/lib/python3.4/site-packages/django/db/models/query.py", line 334, in get
    self.model._meta.object_name
django.contrib.sites.models.DoesNotExist: Site matching query does not exist.
ERROR 2016-06-07 18:51:59,166 base.py handle_uncaught_exception 256 Internal Server Error: /admin/login/
Traceback (most recent call last):
  File "/home/guinsly/.pyenv/versions/django1.9.3.4.3/lib/python3.4/site-packages/django/core/handlers/base.py", line 132, in get_response
    response = wrapped_callback(request, *callback_args, **callback_kwargs)
  File "/home/guinsly/.pyenv/versions/django1.9.3.4.3/lib/python3.4/site-packages/django/views/decorators/cache.py", line 57, in _wrapped_view_func
    response = view_func(request, *args, **kwargs)
  File "/home/guinsly/.pyenv/versions/django1.9.3.4.3/lib/python3.4/site-packages/django/contrib/admin/sites.py", line 400, in login
    return login(request, **defaults)
  File "/home/guinsly/.pyenv/versions/django1.9.3.4.3/lib/python3.4/site-packages/django/views/decorators/debug.py", line 76, in sensitive_post_parameters_wrapper
    return view(request, *args, **kwargs)
  File "/home/guinsly/.pyenv/versions/django1.9.3.4.3/lib/python3.4/site-packages/django/utils/decorators.py", line 110, in _wrapped_view
    response = view_func(request, *args, **kwargs)
  File "/home/guinsly/.pyenv/versions/django1.9.3.4.3/lib/python3.4/site-packages/django/views/decorators/cache.py", line 57, in _wrapped_view_func
    response = view_func(request, *args, **kwargs)
  File "/home/guinsly/.pyenv/versions/django1.9.3.4.3/lib/python3.4/site-packages/django/contrib/auth/views.py", line 57, in login
    current_site = get_current_site(request)
  File "/home/guinsly/.pyenv/versions/django1.9.3.4.3/lib/python3.4/site-packages/django/contrib/sites/shortcuts.py", line 15, in get_current_site
    return Site.objects.get_current(request)
  File "/home/guinsly/.pyenv/versions/django1.9.3.4.3/lib/python3.4/site-packages/django/contrib/sites/models.py", line 62, in get_current
    return self._get_site_by_request(request)
  File "/home/guinsly/.pyenv/versions/django1.9.3.4.3/lib/python3.4/site-packages/django/contrib/sites/models.py", line 46, in _get_site_by_request
    site = self.get(domain__iexact=host)
  File "/home/guinsly/.pyenv/versions/django1.9.3.4.3/lib/python3.4/site-packages/django/db/models/manager.py", line 127, in manager_method
    return getattr(self.get_queryset(), name)(*args, **kwargs)
  File "/home/guinsly/.pyenv/versions/django1.9.3.4.3/lib/python3.4/site-packages/django/db/models/query.py", line 334, in get
    self.model._meta.object_name
django.contrib.sites.models.DoesNotExist: Site matching query does not exist.
ERROR 2016-06-07 18:58:07,666 base.py handle_uncaught_exception 256 Internal Server Error: /admin/websites/website404/add/
Traceback (most recent call last):
  File "/home/guinsly/.pyenv/versions/django1.9.3.4.3/lib/python3.4/site-packages/django/core/handlers/base.py", line 132, in get_response
    response = wrapped_callback(request, *callback_args, **callback_kwargs)
  File "/home/guinsly/.pyenv/versions/django1.9.3.4.3/lib/python3.4/site-packages/django/contrib/admin/options.py", line 618, in wrapper
    return self.admin_site.admin_view(view)(*args, **kwargs)
  File "/home/guinsly/.pyenv/versions/django1.9.3.4.3/lib/python3.4/site-packages/django/utils/decorators.py", line 110, in _wrapped_view
    response = view_func(request, *args, **kwargs)
  File "/home/guinsly/.pyenv/versions/django1.9.3.4.3/lib/python3.4/site-packages/django/views/decorators/cache.py", line 57, in _wrapped_view_func
    response = view_func(request, *args, **kwargs)
  File "/home/guinsly/.pyenv/versions/django1.9.3.4.3/lib/python3.4/site-packages/django/contrib/admin/sites.py", line 233, in inner
    return view(request, *args, **kwargs)
  File "/home/guinsly/.pyenv/versions/django1.9.3.4.3/lib/python3.4/site-packages/django/contrib/admin/options.py", line 1518, in add_view
    return self.changeform_view(request, None, form_url, extra_context)
  File "/home/guinsly/.pyenv/versions/django1.9.3.4.3/lib/python3.4/site-packages/django/utils/decorators.py", line 34, in _wrapper
    return bound_func(*args, **kwargs)
  File "/home/guinsly/.pyenv/versions/django1.9.3.4.3/lib/python3.4/site-packages/django/utils/decorators.py", line 110, in _wrapped_view
    response = view_func(request, *args, **kwargs)
  File "/home/guinsly/.pyenv/versions/django1.9.3.4.3/lib/python3.4/site-packages/django/utils/decorators.py", line 30, in bound_func
    return func.__get__(self, type(self))(*args2, **kwargs2)
  File "/home/guinsly/.pyenv/versions/3.4.4/lib/python3.4/contextlib.py", line 30, in inner
    return func(*args, **kwds)
  File "/home/guinsly/.pyenv/versions/django1.9.3.4.3/lib/python3.4/site-packages/django/contrib/admin/options.py", line 1469, in changeform_view
    self.save_model(request, new_object, form, not add)
  File "/home/guinsly/.pyenv/versions/django1.9.3.4.3/lib/python3.4/site-packages/django/contrib/admin/options.py", line 1080, in save_model
    obj.save()
  File "/home/guinsly/.pyenv/versions/django1.9.3.4.3/lib/python3.4/site-packages/django/db/models/base.py", line 734, in save
    force_update=force_update, update_fields=update_fields)
  File "/home/guinsly/.pyenv/versions/django1.9.3.4.3/lib/python3.4/site-packages/django/db/models/base.py", line 771, in save_base
    update_fields=update_fields, raw=raw, using=using)
  File "/home/guinsly/.pyenv/versions/django1.9.3.4.3/lib/python3.4/site-packages/django/dispatch/dispatcher.py", line 189, in send
    response = receiver(signal=self, sender=sender, **named)
  File "/home/guinsly/.pyenv/versions/django1.9.3.4.3/lib/python3.4/site-packages/imagekit/specs/sourcegroups.py", line 33, in receiver
    fn(self, sender=sender, **kwargs)
  File "/home/guinsly/.pyenv/versions/django1.9.3.4.3/lib/python3.4/site-packages/imagekit/specs/sourcegroups.py", line 94, in post_save_receiver
    new_hashes = self.update_source_hashes(instance)
  File "/home/guinsly/.pyenv/versions/django1.9.3.4.3/lib/python3.4/site-packages/imagekit/specs/sourcegroups.py", line 77, in update_source_hashes
    for attname in self.get_source_fields(instance))
  File "/home/guinsly/.pyenv/versions/django1.9.3.4.3/lib/python3.4/site-packages/imagekit/specs/sourcegroups.py", line 77, in <genexpr>
    for attname in self.get_source_fields(instance))
AttributeError: 'website404' object has no attribute 'avatar'
ERROR 2016-06-07 18:58:07,666 base.py handle_uncaught_exception 256 Internal Server Error: /admin/websites/website404/add/
Traceback (most recent call last):
  File "/home/guinsly/.pyenv/versions/django1.9.3.4.3/lib/python3.4/site-packages/django/core/handlers/base.py", line 132, in get_response
    response = wrapped_callback(request, *callback_args, **callback_kwargs)
  File "/home/guinsly/.pyenv/versions/django1.9.3.4.3/lib/python3.4/site-packages/django/contrib/admin/options.py", line 618, in wrapper
    return self.admin_site.admin_view(view)(*args, **kwargs)
  File "/home/guinsly/.pyenv/versions/django1.9.3.4.3/lib/python3.4/site-packages/django/utils/decorators.py", line 110, in _wrapped_view
    response = view_func(request, *args, **kwargs)
  File "/home/guinsly/.pyenv/versions/django1.9.3.4.3/lib/python3.4/site-packages/django/views/decorators/cache.py", line 57, in _wrapped_view_func
    response = view_func(request, *args, **kwargs)
  File "/home/guinsly/.pyenv/versions/django1.9.3.4.3/lib/python3.4/site-packages/django/contrib/admin/sites.py", line 233, in inner
    return view(request, *args, **kwargs)
  File "/home/guinsly/.pyenv/versions/django1.9.3.4.3/lib/python3.4/site-packages/django/contrib/admin/options.py", line 1518, in add_view
    return self.changeform_view(request, None, form_url, extra_context)
  File "/home/guinsly/.pyenv/versions/django1.9.3.4.3/lib/python3.4/site-packages/django/utils/decorators.py", line 34, in _wrapper
    return bound_func(*args, **kwargs)
  File "/home/guinsly/.pyenv/versions/django1.9.3.4.3/lib/python3.4/site-packages/django/utils/decorators.py", line 110, in _wrapped_view
    response = view_func(request, *args, **kwargs)
  File "/home/guinsly/.pyenv/versions/django1.9.3.4.3/lib/python3.4/site-packages/django/utils/decorators.py", line 30, in bound_func
    return func.__get__(self, type(self))(*args2, **kwargs2)
  File "/home/guinsly/.pyenv/versions/3.4.4/lib/python3.4/contextlib.py", line 30, in inner
    return func(*args, **kwds)
  File "/home/guinsly/.pyenv/versions/django1.9.3.4.3/lib/python3.4/site-packages/django/contrib/admin/options.py", line 1469, in changeform_view
    self.save_model(request, new_object, form, not add)
  File "/home/guinsly/.pyenv/versions/django1.9.3.4.3/lib/python3.4/site-packages/django/contrib/admin/options.py", line 1080, in save_model
    obj.save()
  File "/home/guinsly/.pyenv/versions/django1.9.3.4.3/lib/python3.4/site-packages/django/db/models/base.py", line 734, in save
    force_update=force_update, update_fields=update_fields)
  File "/home/guinsly/.pyenv/versions/django1.9.3.4.3/lib/python3.4/site-packages/django/db/models/base.py", line 771, in save_base
    update_fields=update_fields, raw=raw, using=using)
  File "/home/guinsly/.pyenv/versions/django1.9.3.4.3/lib/python3.4/site-packages/django/dispatch/dispatcher.py", line 189, in send
    response = receiver(signal=self, sender=sender, **named)
  File "/home/guinsly/.pyenv/versions/django1.9.3.4.3/lib/python3.4/site-packages/imagekit/specs/sourcegroups.py", line 33, in receiver
    fn(self, sender=sender, **kwargs)
  File "/home/guinsly/.pyenv/versions/django1.9.3.4.3/lib/python3.4/site-packages/imagekit/specs/sourcegroups.py", line 94, in post_save_receiver
    new_hashes = self.update_source_hashes(instance)
  File "/home/guinsly/.pyenv/versions/django1.9.3.4.3/lib/python3.4/site-packages/imagekit/specs/sourcegroups.py", line 77, in update_source_hashes
    for attname in self.get_source_fields(instance))
  File "/home/guinsly/.pyenv/versions/django1.9.3.4.3/lib/python3.4/site-packages/imagekit/specs/sourcegroups.py", line 77, in <genexpr>
    for attname in self.get_source_fields(instance))
AttributeError: 'website404' object has no attribute 'avatar'
ERROR 2016-06-07 18:58:07,666 base.py handle_uncaught_exception 256 Internal Server Error: /admin/websites/website404/add/
Traceback (most recent call last):
  File "/home/guinsly/.pyenv/versions/django1.9.3.4.3/lib/python3.4/site-packages/django/core/handlers/base.py", line 132, in get_response
    response = wrapped_callback(request, *callback_args, **callback_kwargs)
  File "/home/guinsly/.pyenv/versions/django1.9.3.4.3/lib/python3.4/site-packages/django/contrib/admin/options.py", line 618, in wrapper
    return self.admin_site.admin_view(view)(*args, **kwargs)
  File "/home/guinsly/.pyenv/versions/django1.9.3.4.3/lib/python3.4/site-packages/django/utils/decorators.py", line 110, in _wrapped_view
    response = view_func(request, *args, **kwargs)
  File "/home/guinsly/.pyenv/versions/django1.9.3.4.3/lib/python3.4/site-packages/django/views/decorators/cache.py", line 57, in _wrapped_view_func
    response = view_func(request, *args, **kwargs)
  File "/home/guinsly/.pyenv/versions/django1.9.3.4.3/lib/python3.4/site-packages/django/contrib/admin/sites.py", line 233, in inner
    return view(request, *args, **kwargs)
  File "/home/guinsly/.pyenv/versions/django1.9.3.4.3/lib/python3.4/site-packages/django/contrib/admin/options.py", line 1518, in add_view
    return self.changeform_view(request, None, form_url, extra_context)
  File "/home/guinsly/.pyenv/versions/django1.9.3.4.3/lib/python3.4/site-packages/django/utils/decorators.py", line 34, in _wrapper
    return bound_func(*args, **kwargs)
  File "/home/guinsly/.pyenv/versions/django1.9.3.4.3/lib/python3.4/site-packages/django/utils/decorators.py", line 110, in _wrapped_view
    response = view_func(request, *args, **kwargs)
  File "/home/guinsly/.pyenv/versions/django1.9.3.4.3/lib/python3.4/site-packages/django/utils/decorators.py", line 30, in bound_func
    return func.__get__(self, type(self))(*args2, **kwargs2)
  File "/home/guinsly/.pyenv/versions/3.4.4/lib/python3.4/contextlib.py", line 30, in inner
    return func(*args, **kwds)
  File "/home/guinsly/.pyenv/versions/django1.9.3.4.3/lib/python3.4/site-packages/django/contrib/admin/options.py", line 1469, in changeform_view
    self.save_model(request, new_object, form, not add)
  File "/home/guinsly/.pyenv/versions/django1.9.3.4.3/lib/python3.4/site-packages/django/contrib/admin/options.py", line 1080, in save_model
    obj.save()
  File "/home/guinsly/.pyenv/versions/django1.9.3.4.3/lib/python3.4/site-packages/django/db/models/base.py", line 734, in save
    force_update=force_update, update_fields=update_fields)
  File "/home/guinsly/.pyenv/versions/django1.9.3.4.3/lib/python3.4/site-packages/django/db/models/base.py", line 771, in save_base
    update_fields=update_fields, raw=raw, using=using)
  File "/home/guinsly/.pyenv/versions/django1.9.3.4.3/lib/python3.4/site-packages/django/dispatch/dispatcher.py", line 189, in send
    response = receiver(signal=self, sender=sender, **named)
  File "/home/guinsly/.pyenv/versions/django1.9.3.4.3/lib/python3.4/site-packages/imagekit/specs/sourcegroups.py", line 33, in receiver
    fn(self, sender=sender, **kwargs)
  File "/home/guinsly/.pyenv/versions/django1.9.3.4.3/lib/python3.4/site-packages/imagekit/specs/sourcegroups.py", line 94, in post_save_receiver
    new_hashes = self.update_source_hashes(instance)
  File "/home/guinsly/.pyenv/versions/django1.9.3.4.3/lib/python3.4/site-packages/imagekit/specs/sourcegroups.py", line 77, in update_source_hashes
    for attname in self.get_source_fields(instance))
  File "/home/guinsly/.pyenv/versions/django1.9.3.4.3/lib/python3.4/site-packages/imagekit/specs/sourcegroups.py", line 77, in <genexpr>
    for attname in self.get_source_fields(instance))
AttributeError: 'website404' object has no attribute 'avatar'
ERROR 2016-06-07 19:15:59,953 base.py handle_uncaught_exception 256 Internal Server Error: /
Traceback (most recent call last):
  File "/home/guinsly/.pyenv/versions/django1.9.3.4.3/lib/python3.4/site-packages/django/core/handlers/base.py", line 164, in get_response
    response = response.render()
  File "/home/guinsly/.pyenv/versions/django1.9.3.4.3/lib/python3.4/site-packages/django/template/response.py", line 158, in render
    self.content = self.rendered_content
  File "/home/guinsly/.pyenv/versions/django1.9.3.4.3/lib/python3.4/site-packages/django/template/response.py", line 133, in rendered_content
    template = self._resolve_template(self.template_name)
  File "/home/guinsly/.pyenv/versions/django1.9.3.4.3/lib/python3.4/site-packages/django/template/response.py", line 88, in _resolve_template
    new_template = self.resolve_template(template)
  File "/home/guinsly/.pyenv/versions/django1.9.3.4.3/lib/python3.4/site-packages/django/template/response.py", line 78, in resolve_template
    return loader.select_template(template, using=self.using)
  File "/home/guinsly/.pyenv/versions/django1.9.3.4.3/lib/python3.4/site-packages/django/template/loader.py", line 76, in select_template
    raise TemplateDoesNotExist(', '.join(template_name_list))
django.template.base.TemplateDoesNotExist: websites/website404_list.html
ERROR 2016-06-07 19:15:59,953 base.py handle_uncaught_exception 256 Internal Server Error: /
Traceback (most recent call last):
  File "/home/guinsly/.pyenv/versions/django1.9.3.4.3/lib/python3.4/site-packages/django/core/handlers/base.py", line 164, in get_response
    response = response.render()
  File "/home/guinsly/.pyenv/versions/django1.9.3.4.3/lib/python3.4/site-packages/django/template/response.py", line 158, in render
    self.content = self.rendered_content
  File "/home/guinsly/.pyenv/versions/django1.9.3.4.3/lib/python3.4/site-packages/django/template/response.py", line 133, in rendered_content
    template = self._resolve_template(self.template_name)
  File "/home/guinsly/.pyenv/versions/django1.9.3.4.3/lib/python3.4/site-packages/django/template/response.py", line 88, in _resolve_template
    new_template = self.resolve_template(template)
  File "/home/guinsly/.pyenv/versions/django1.9.3.4.3/lib/python3.4/site-packages/django/template/response.py", line 78, in resolve_template
    return loader.select_template(template, using=self.using)
  File "/home/guinsly/.pyenv/versions/django1.9.3.4.3/lib/python3.4/site-packages/django/template/loader.py", line 76, in select_template
    raise TemplateDoesNotExist(', '.join(template_name_list))
django.template.base.TemplateDoesNotExist: websites/website404_list.html
ERROR 2016-06-07 19:15:59,953 base.py handle_uncaught_exception 256 Internal Server Error: /
Traceback (most recent call last):
  File "/home/guinsly/.pyenv/versions/django1.9.3.4.3/lib/python3.4/site-packages/django/core/handlers/base.py", line 164, in get_response
    response = response.render()
  File "/home/guinsly/.pyenv/versions/django1.9.3.4.3/lib/python3.4/site-packages/django/template/response.py", line 158, in render
    self.content = self.rendered_content
  File "/home/guinsly/.pyenv/versions/django1.9.3.4.3/lib/python3.4/site-packages/django/template/response.py", line 133, in rendered_content
    template = self._resolve_template(self.template_name)
  File "/home/guinsly/.pyenv/versions/django1.9.3.4.3/lib/python3.4/site-packages/django/template/response.py", line 88, in _resolve_template
    new_template = self.resolve_template(template)
  File "/home/guinsly/.pyenv/versions/django1.9.3.4.3/lib/python3.4/site-packages/django/template/response.py", line 78, in resolve_template
    return loader.select_template(template, using=self.using)
  File "/home/guinsly/.pyenv/versions/django1.9.3.4.3/lib/python3.4/site-packages/django/template/loader.py", line 76, in select_template
    raise TemplateDoesNotExist(', '.join(template_name_list))
django.template.base.TemplateDoesNotExist: websites/website404_list.html
ERROR 2016-06-07 19:51:30,859 base.py handle_uncaught_exception 256 Internal Server Error: /
Traceback (most recent call last):
  File "/home/guinsly/.pyenv/versions/django1.9.3.4.3/lib/python3.4/site-packages/django/template/defaulttags.py", line 501, in render
    current_app=current_app)
  File "/home/guinsly/.pyenv/versions/django1.9.3.4.3/lib/python3.4/site-packages/django/core/urlresolvers.py", line 578, in reverse
    return force_text(iri_to_uri(resolver._reverse_with_prefix(view, prefix, *args, **kwargs)))
  File "/home/guinsly/.pyenv/versions/django1.9.3.4.3/lib/python3.4/site-packages/django/core/urlresolvers.py", line 495, in _reverse_with_prefix
    (lookup_view_s, args, kwargs, len(patterns), patterns))
django.core.urlresolvers.NoReverseMatch: Reverse for 'settings.websites-detail' with arguments '('',)' and keyword arguments '{}' not found. 0 pattern(s) tried: []

During handling of the above exception, another exception occurred:

Traceback (most recent call last):
  File "/home/guinsly/.pyenv/versions/django1.9.3.4.3/lib/python3.4/site-packages/django/core/handlers/base.py", line 164, in get_response
    response = response.render()
  File "/home/guinsly/.pyenv/versions/django1.9.3.4.3/lib/python3.4/site-packages/django/template/response.py", line 158, in render
    self.content = self.rendered_content
  File "/home/guinsly/.pyenv/versions/django1.9.3.4.3/lib/python3.4/site-packages/django/template/response.py", line 135, in rendered_content
    content = template.render(context, self._request)
  File "/home/guinsly/.pyenv/versions/django1.9.3.4.3/lib/python3.4/site-packages/django/template/backends/django.py", line 74, in render
    return self.template.render(context)
  File "/home/guinsly/.pyenv/versions/django1.9.3.4.3/lib/python3.4/site-packages/django/template/base.py", line 210, in render
    return self._render(context)
  File "/home/guinsly/.pyenv/versions/django1.9.3.4.3/lib/python3.4/site-packages/django/test/utils.py", line 96, in instrumented_test_render
    return self.nodelist.render(context)
  File "/home/guinsly/.pyenv/versions/django1.9.3.4.3/lib/python3.4/site-packages/django/template/base.py", line 905, in render
    bit = self.render_node(node, context)
  File "/home/guinsly/.pyenv/versions/django1.9.3.4.3/lib/python3.4/site-packages/django/template/debug.py", line 79, in render_node
    return node.render(context)
  File "/home/guinsly/.pyenv/versions/django1.9.3.4.3/lib/python3.4/site-packages/django/template/defaulttags.py", line 217, in render
    nodelist.append(node.render(context))
  File "/home/guinsly/.pyenv/versions/django1.9.3.4.3/lib/python3.4/site-packages/django/template/defaulttags.py", line 507, in render
    six.reraise(*exc_info)
  File "/home/guinsly/.pyenv/versions/django1.9.3.4.3/lib/python3.4/site-packages/django/utils/six.py", line 686, in reraise
    raise value
  File "/home/guinsly/.pyenv/versions/django1.9.3.4.3/lib/python3.4/site-packages/django/template/defaulttags.py", line 493, in render
    url = reverse(view_name, args=args, kwargs=kwargs, current_app=current_app)
  File "/home/guinsly/.pyenv/versions/django1.9.3.4.3/lib/python3.4/site-packages/django/core/urlresolvers.py", line 578, in reverse
    return force_text(iri_to_uri(resolver._reverse_with_prefix(view, prefix, *args, **kwargs)))
  File "/home/guinsly/.pyenv/versions/django1.9.3.4.3/lib/python3.4/site-packages/django/core/urlresolvers.py", line 495, in _reverse_with_prefix
    (lookup_view_s, args, kwargs, len(patterns), patterns))
django.core.urlresolvers.NoReverseMatch: Reverse for 'websites-detail' with arguments '('',)' and keyword arguments '{}' not found. 1 pattern(s) tried: ['(?P<slug>[-\\w]+)/$']
ERROR 2016-06-07 19:51:30,859 base.py handle_uncaught_exception 256 Internal Server Error: /
Traceback (most recent call last):
  File "/home/guinsly/.pyenv/versions/django1.9.3.4.3/lib/python3.4/site-packages/django/template/defaulttags.py", line 501, in render
    current_app=current_app)
  File "/home/guinsly/.pyenv/versions/django1.9.3.4.3/lib/python3.4/site-packages/django/core/urlresolvers.py", line 578, in reverse
    return force_text(iri_to_uri(resolver._reverse_with_prefix(view, prefix, *args, **kwargs)))
  File "/home/guinsly/.pyenv/versions/django1.9.3.4.3/lib/python3.4/site-packages/django/core/urlresolvers.py", line 495, in _reverse_with_prefix
    (lookup_view_s, args, kwargs, len(patterns), patterns))
django.core.urlresolvers.NoReverseMatch: Reverse for 'settings.websites-detail' with arguments '('',)' and keyword arguments '{}' not found. 0 pattern(s) tried: []

During handling of the above exception, another exception occurred:

Traceback (most recent call last):
  File "/home/guinsly/.pyenv/versions/django1.9.3.4.3/lib/python3.4/site-packages/django/core/handlers/base.py", line 164, in get_response
    response = response.render()
  File "/home/guinsly/.pyenv/versions/django1.9.3.4.3/lib/python3.4/site-packages/django/template/response.py", line 158, in render
    self.content = self.rendered_content
  File "/home/guinsly/.pyenv/versions/django1.9.3.4.3/lib/python3.4/site-packages/django/template/response.py", line 135, in rendered_content
    content = template.render(context, self._request)
  File "/home/guinsly/.pyenv/versions/django1.9.3.4.3/lib/python3.4/site-packages/django/template/backends/django.py", line 74, in render
    return self.template.render(context)
  File "/home/guinsly/.pyenv/versions/django1.9.3.4.3/lib/python3.4/site-packages/django/template/base.py", line 210, in render
    return self._render(context)
  File "/home/guinsly/.pyenv/versions/django1.9.3.4.3/lib/python3.4/site-packages/django/test/utils.py", line 96, in instrumented_test_render
    return self.nodelist.render(context)
  File "/home/guinsly/.pyenv/versions/django1.9.3.4.3/lib/python3.4/site-packages/django/template/base.py", line 905, in render
    bit = self.render_node(node, context)
  File "/home/guinsly/.pyenv/versions/django1.9.3.4.3/lib/python3.4/site-packages/django/template/debug.py", line 79, in render_node
    return node.render(context)
  File "/home/guinsly/.pyenv/versions/django1.9.3.4.3/lib/python3.4/site-packages/django/template/defaulttags.py", line 217, in render
    nodelist.append(node.render(context))
  File "/home/guinsly/.pyenv/versions/django1.9.3.4.3/lib/python3.4/site-packages/django/template/defaulttags.py", line 507, in render
    six.reraise(*exc_info)
  File "/home/guinsly/.pyenv/versions/django1.9.3.4.3/lib/python3.4/site-packages/django/utils/six.py", line 686, in reraise
    raise value
  File "/home/guinsly/.pyenv/versions/django1.9.3.4.3/lib/python3.4/site-packages/django/template/defaulttags.py", line 493, in render
    url = reverse(view_name, args=args, kwargs=kwargs, current_app=current_app)
  File "/home/guinsly/.pyenv/versions/django1.9.3.4.3/lib/python3.4/site-packages/django/core/urlresolvers.py", line 578, in reverse
    return force_text(iri_to_uri(resolver._reverse_with_prefix(view, prefix, *args, **kwargs)))
  File "/home/guinsly/.pyenv/versions/django1.9.3.4.3/lib/python3.4/site-packages/django/core/urlresolvers.py", line 495, in _reverse_with_prefix
    (lookup_view_s, args, kwargs, len(patterns), patterns))
django.core.urlresolvers.NoReverseMatch: Reverse for 'websites-detail' with arguments '('',)' and keyword arguments '{}' not found. 1 pattern(s) tried: ['(?P<slug>[-\\w]+)/$']
ERROR 2016-06-07 19:51:30,859 base.py handle_uncaught_exception 256 Internal Server Error: /
Traceback (most recent call last):
  File "/home/guinsly/.pyenv/versions/django1.9.3.4.3/lib/python3.4/site-packages/django/template/defaulttags.py", line 501, in render
    current_app=current_app)
  File "/home/guinsly/.pyenv/versions/django1.9.3.4.3/lib/python3.4/site-packages/django/core/urlresolvers.py", line 578, in reverse
    return force_text(iri_to_uri(resolver._reverse_with_prefix(view, prefix, *args, **kwargs)))
  File "/home/guinsly/.pyenv/versions/django1.9.3.4.3/lib/python3.4/site-packages/django/core/urlresolvers.py", line 495, in _reverse_with_prefix
    (lookup_view_s, args, kwargs, len(patterns), patterns))
django.core.urlresolvers.NoReverseMatch: Reverse for 'settings.websites-detail' with arguments '('',)' and keyword arguments '{}' not found. 0 pattern(s) tried: []

During handling of the above exception, another exception occurred:

Traceback (most recent call last):
  File "/home/guinsly/.pyenv/versions/django1.9.3.4.3/lib/python3.4/site-packages/django/core/handlers/base.py", line 164, in get_response
    response = response.render()
  File "/home/guinsly/.pyenv/versions/django1.9.3.4.3/lib/python3.4/site-packages/django/template/response.py", line 158, in render
    self.content = self.rendered_content
  File "/home/guinsly/.pyenv/versions/django1.9.3.4.3/lib/python3.4/site-packages/django/template/response.py", line 135, in rendered_content
    content = template.render(context, self._request)
  File "/home/guinsly/.pyenv/versions/django1.9.3.4.3/lib/python3.4/site-packages/django/template/backends/django.py", line 74, in render
    return self.template.render(context)
  File "/home/guinsly/.pyenv/versions/django1.9.3.4.3/lib/python3.4/site-packages/django/template/base.py", line 210, in render
    return self._render(context)
  File "/home/guinsly/.pyenv/versions/django1.9.3.4.3/lib/python3.4/site-packages/django/test/utils.py", line 96, in instrumented_test_render
    return self.nodelist.render(context)
  File "/home/guinsly/.pyenv/versions/django1.9.3.4.3/lib/python3.4/site-packages/django/template/base.py", line 905, in render
    bit = self.render_node(node, context)
  File "/home/guinsly/.pyenv/versions/django1.9.3.4.3/lib/python3.4/site-packages/django/template/debug.py", line 79, in render_node
    return node.render(context)
  File "/home/guinsly/.pyenv/versions/django1.9.3.4.3/lib/python3.4/site-packages/django/template/defaulttags.py", line 217, in render
    nodelist.append(node.render(context))
  File "/home/guinsly/.pyenv/versions/django1.9.3.4.3/lib/python3.4/site-packages/django/template/defaulttags.py", line 507, in render
    six.reraise(*exc_info)
  File "/home/guinsly/.pyenv/versions/django1.9.3.4.3/lib/python3.4/site-packages/django/utils/six.py", line 686, in reraise
    raise value
  File "/home/guinsly/.pyenv/versions/django1.9.3.4.3/lib/python3.4/site-packages/django/template/defaulttags.py", line 493, in render
    url = reverse(view_name, args=args, kwargs=kwargs, current_app=current_app)
  File "/home/guinsly/.pyenv/versions/django1.9.3.4.3/lib/python3.4/site-packages/django/core/urlresolvers.py", line 578, in reverse
    return force_text(iri_to_uri(resolver._reverse_with_prefix(view, prefix, *args, **kwargs)))
  File "/home/guinsly/.pyenv/versions/django1.9.3.4.3/lib/python3.4/site-packages/django/core/urlresolvers.py", line 495, in _reverse_with_prefix
    (lookup_view_s, args, kwargs, len(patterns), patterns))
django.core.urlresolvers.NoReverseMatch: Reverse for 'websites-detail' with arguments '('',)' and keyword arguments '{}' not found. 1 pattern(s) tried: ['(?P<slug>[-\\w]+)/$']
ERROR 2016-06-07 20:00:57,112 base.py handle_uncaught_exception 256 Internal Server Error: /radio-canada/
Traceback (most recent call last):
  File "/home/guinsly/.pyenv/versions/django1.9.3.4.3/lib/python3.4/site-packages/django/template/base.py", line 819, in _resolve_lookup
    current = current[bit]
TypeError: 'ImageCacheFile' object is not subscriptable

During handling of the above exception, another exception occurred:

Traceback (most recent call last):
  File "/home/guinsly/.pyenv/versions/django1.9.3.4.3/lib/python3.4/site-packages/django/core/handlers/base.py", line 164, in get_response
    response = response.render()
  File "/home/guinsly/.pyenv/versions/django1.9.3.4.3/lib/python3.4/site-packages/django/template/response.py", line 158, in render
    self.content = self.rendered_content
  File "/home/guinsly/.pyenv/versions/django1.9.3.4.3/lib/python3.4/site-packages/django/template/response.py", line 135, in rendered_content
    content = template.render(context, self._request)
  File "/home/guinsly/.pyenv/versions/django1.9.3.4.3/lib/python3.4/site-packages/django/template/backends/django.py", line 74, in render
    return self.template.render(context)
  File "/home/guinsly/.pyenv/versions/django1.9.3.4.3/lib/python3.4/site-packages/django/template/base.py", line 210, in render
    return self._render(context)
  File "/home/guinsly/.pyenv/versions/django1.9.3.4.3/lib/python3.4/site-packages/django/test/utils.py", line 96, in instrumented_test_render
    return self.nodelist.render(context)
  File "/home/guinsly/.pyenv/versions/django1.9.3.4.3/lib/python3.4/site-packages/django/template/base.py", line 905, in render
    bit = self.render_node(node, context)
  File "/home/guinsly/.pyenv/versions/django1.9.3.4.3/lib/python3.4/site-packages/django/template/debug.py", line 79, in render_node
    return node.render(context)
  File "/home/guinsly/.pyenv/versions/django1.9.3.4.3/lib/python3.4/site-packages/django/template/debug.py", line 89, in render
    output = self.filter_expression.resolve(context)
  File "/home/guinsly/.pyenv/versions/django1.9.3.4.3/lib/python3.4/site-packages/django/template/base.py", line 648, in resolve
    obj = self.var.resolve(context)
  File "/home/guinsly/.pyenv/versions/django1.9.3.4.3/lib/python3.4/site-packages/django/template/base.py", line 789, in resolve
    value = self._resolve_lookup(context)
  File "/home/guinsly/.pyenv/versions/django1.9.3.4.3/lib/python3.4/site-packages/django/template/base.py", line 827, in _resolve_lookup
    current = getattr(current, bit)
  File "/home/guinsly/.pyenv/versions/django1.9.3.4.3/lib/python3.4/site-packages/imagekit/cachefiles/__init__.py", line 84, in url
    return self._storage_attr('url')
  File "/home/guinsly/.pyenv/versions/django1.9.3.4.3/lib/python3.4/site-packages/imagekit/cachefiles/__init__.py", line 74, in _storage_attr
    existence_required.send(sender=self, file=self)
  File "/home/guinsly/.pyenv/versions/django1.9.3.4.3/lib/python3.4/site-packages/django/dispatch/dispatcher.py", line 189, in send
    response = receiver(signal=self, sender=sender, **named)
  File "/home/guinsly/.pyenv/versions/django1.9.3.4.3/lib/python3.4/site-packages/imagekit/registry.py", line 53, in existence_required_receiver
    self._receive(file, 'on_existence_required')
  File "/home/guinsly/.pyenv/versions/django1.9.3.4.3/lib/python3.4/site-packages/imagekit/registry.py", line 61, in _receive
    call_strategy_method(file, callback)
  File "/home/guinsly/.pyenv/versions/django1.9.3.4.3/lib/python3.4/site-packages/imagekit/utils.py", line 151, in call_strategy_method
    fn(file)
  File "/home/guinsly/.pyenv/versions/django1.9.3.4.3/lib/python3.4/site-packages/imagekit/cachefiles/strategies.py", line 15, in on_existence_required
    file.generate()
  File "/home/guinsly/.pyenv/versions/django1.9.3.4.3/lib/python3.4/site-packages/imagekit/cachefiles/__init__.py", line 93, in generate
    self.cachefile_backend.generate(self, force)
  File "/home/guinsly/.pyenv/versions/django1.9.3.4.3/lib/python3.4/site-packages/imagekit/cachefiles/backends.py", line 109, in generate
    self.generate_now(file, force=force)
  File "/home/guinsly/.pyenv/versions/django1.9.3.4.3/lib/python3.4/site-packages/imagekit/cachefiles/backends.py", line 96, in generate_now
    file._generate()
  File "/home/guinsly/.pyenv/versions/django1.9.3.4.3/lib/python3.4/site-packages/imagekit/cachefiles/__init__.py", line 97, in _generate
    content = generate(self.generator)
  File "/home/guinsly/.pyenv/versions/django1.9.3.4.3/lib/python3.4/site-packages/imagekit/utils.py", line 134, in generate
    content = generator.generate()
  File "/home/guinsly/.pyenv/versions/django1.9.3.4.3/lib/python3.4/site-packages/imagekit/specs/__init__.py", line 149, in generate
    img = open_image(self.source)
  File "/home/guinsly/.pyenv/versions/django1.9.3.4.3/lib/python3.4/site-packages/pilkit/utils.py", line 21, in open_image
    target.seek(0)
  File "/home/guinsly/.pyenv/versions/django1.9.3.4.3/lib/python3.4/site-packages/django/core/files/utils.py", line 20, in <lambda>
    seek = property(lambda self: self.file.seek)
  File "/home/guinsly/.pyenv/versions/django1.9.3.4.3/lib/python3.4/site-packages/django/db/models/fields/files.py", line 51, in _get_file
    self._file = self.storage.open(self.name, 'rb')
  File "/home/guinsly/.pyenv/versions/django1.9.3.4.3/lib/python3.4/site-packages/django/core/files/storage.py", line 37, in open
    return self._open(name, mode)
  File "/home/guinsly/.pyenv/versions/django1.9.3.4.3/lib/python3.4/site-packages/django/core/files/storage.py", line 201, in _open
    return File(open(self.path(name), mode))
FileNotFoundError: [Errno 2] No such file or directory: '/home/guinsly/development/public/project/ohmy404/media/404/2016/06/07/Screenshot_from_2016-04-27_095930.png'
ERROR 2016-06-07 20:00:57,112 base.py handle_uncaught_exception 256 Internal Server Error: /radio-canada/
Traceback (most recent call last):
  File "/home/guinsly/.pyenv/versions/django1.9.3.4.3/lib/python3.4/site-packages/django/template/base.py", line 819, in _resolve_lookup
    current = current[bit]
TypeError: 'ImageCacheFile' object is not subscriptable

During handling of the above exception, another exception occurred:

Traceback (most recent call last):
  File "/home/guinsly/.pyenv/versions/django1.9.3.4.3/lib/python3.4/site-packages/django/core/handlers/base.py", line 164, in get_response
    response = response.render()
  File "/home/guinsly/.pyenv/versions/django1.9.3.4.3/lib/python3.4/site-packages/django/template/response.py", line 158, in render
    self.content = self.rendered_content
  File "/home/guinsly/.pyenv/versions/django1.9.3.4.3/lib/python3.4/site-packages/django/template/response.py", line 135, in rendered_content
    content = template.render(context, self._request)
  File "/home/guinsly/.pyenv/versions/django1.9.3.4.3/lib/python3.4/site-packages/django/template/backends/django.py", line 74, in render
    return self.template.render(context)
  File "/home/guinsly/.pyenv/versions/django1.9.3.4.3/lib/python3.4/site-packages/django/template/base.py", line 210, in render
    return self._render(context)
  File "/home/guinsly/.pyenv/versions/django1.9.3.4.3/lib/python3.4/site-packages/django/test/utils.py", line 96, in instrumented_test_render
    return self.nodelist.render(context)
  File "/home/guinsly/.pyenv/versions/django1.9.3.4.3/lib/python3.4/site-packages/django/template/base.py", line 905, in render
    bit = self.render_node(node, context)
  File "/home/guinsly/.pyenv/versions/django1.9.3.4.3/lib/python3.4/site-packages/django/template/debug.py", line 79, in render_node
    return node.render(context)
  File "/home/guinsly/.pyenv/versions/django1.9.3.4.3/lib/python3.4/site-packages/django/template/debug.py", line 89, in render
    output = self.filter_expression.resolve(context)
  File "/home/guinsly/.pyenv/versions/django1.9.3.4.3/lib/python3.4/site-packages/django/template/base.py", line 648, in resolve
    obj = self.var.resolve(context)
  File "/home/guinsly/.pyenv/versions/django1.9.3.4.3/lib/python3.4/site-packages/django/template/base.py", line 789, in resolve
    value = self._resolve_lookup(context)
  File "/home/guinsly/.pyenv/versions/django1.9.3.4.3/lib/python3.4/site-packages/django/template/base.py", line 827, in _resolve_lookup
    current = getattr(current, bit)
  File "/home/guinsly/.pyenv/versions/django1.9.3.4.3/lib/python3.4/site-packages/imagekit/cachefiles/__init__.py", line 84, in url
    return self._storage_attr('url')
  File "/home/guinsly/.pyenv/versions/django1.9.3.4.3/lib/python3.4/site-packages/imagekit/cachefiles/__init__.py", line 74, in _storage_attr
    existence_required.send(sender=self, file=self)
  File "/home/guinsly/.pyenv/versions/django1.9.3.4.3/lib/python3.4/site-packages/django/dispatch/dispatcher.py", line 189, in send
    response = receiver(signal=self, sender=sender, **named)
  File "/home/guinsly/.pyenv/versions/django1.9.3.4.3/lib/python3.4/site-packages/imagekit/registry.py", line 53, in existence_required_receiver
    self._receive(file, 'on_existence_required')
  File "/home/guinsly/.pyenv/versions/django1.9.3.4.3/lib/python3.4/site-packages/imagekit/registry.py", line 61, in _receive
    call_strategy_method(file, callback)
  File "/home/guinsly/.pyenv/versions/django1.9.3.4.3/lib/python3.4/site-packages/imagekit/utils.py", line 151, in call_strategy_method
    fn(file)
  File "/home/guinsly/.pyenv/versions/django1.9.3.4.3/lib/python3.4/site-packages/imagekit/cachefiles/strategies.py", line 15, in on_existence_required
    file.generate()
  File "/home/guinsly/.pyenv/versions/django1.9.3.4.3/lib/python3.4/site-packages/imagekit/cachefiles/__init__.py", line 93, in generate
    self.cachefile_backend.generate(self, force)
  File "/home/guinsly/.pyenv/versions/django1.9.3.4.3/lib/python3.4/site-packages/imagekit/cachefiles/backends.py", line 109, in generate
    self.generate_now(file, force=force)
  File "/home/guinsly/.pyenv/versions/django1.9.3.4.3/lib/python3.4/site-packages/imagekit/cachefiles/backends.py", line 96, in generate_now
    file._generate()
  File "/home/guinsly/.pyenv/versions/django1.9.3.4.3/lib/python3.4/site-packages/imagekit/cachefiles/__init__.py", line 97, in _generate
    content = generate(self.generator)
  File "/home/guinsly/.pyenv/versions/django1.9.3.4.3/lib/python3.4/site-packages/imagekit/utils.py", line 134, in generate
    content = generator.generate()
  File "/home/guinsly/.pyenv/versions/django1.9.3.4.3/lib/python3.4/site-packages/imagekit/specs/__init__.py", line 149, in generate
    img = open_image(self.source)
  File "/home/guinsly/.pyenv/versions/django1.9.3.4.3/lib/python3.4/site-packages/pilkit/utils.py", line 21, in open_image
    target.seek(0)
  File "/home/guinsly/.pyenv/versions/django1.9.3.4.3/lib/python3.4/site-packages/django/core/files/utils.py", line 20, in <lambda>
    seek = property(lambda self: self.file.seek)
  File "/home/guinsly/.pyenv/versions/django1.9.3.4.3/lib/python3.4/site-packages/django/db/models/fields/files.py", line 51, in _get_file
    self._file = self.storage.open(self.name, 'rb')
  File "/home/guinsly/.pyenv/versions/django1.9.3.4.3/lib/python3.4/site-packages/django/core/files/storage.py", line 37, in open
    return self._open(name, mode)
  File "/home/guinsly/.pyenv/versions/django1.9.3.4.3/lib/python3.4/site-packages/django/core/files/storage.py", line 201, in _open
    return File(open(self.path(name), mode))
FileNotFoundError: [Errno 2] No such file or directory: '/home/guinsly/development/public/project/ohmy404/media/404/2016/06/07/Screenshot_from_2016-04-27_095930.png'
ERROR 2016-06-07 20:00:57,112 base.py handle_uncaught_exception 256 Internal Server Error: /radio-canada/
Traceback (most recent call last):
  File "/home/guinsly/.pyenv/versions/django1.9.3.4.3/lib/python3.4/site-packages/django/template/base.py", line 819, in _resolve_lookup
    current = current[bit]
TypeError: 'ImageCacheFile' object is not subscriptable

During handling of the above exception, another exception occurred:

Traceback (most recent call last):
  File "/home/guinsly/.pyenv/versions/django1.9.3.4.3/lib/python3.4/site-packages/django/core/handlers/base.py", line 164, in get_response
    response = response.render()
  File "/home/guinsly/.pyenv/versions/django1.9.3.4.3/lib/python3.4/site-packages/django/template/response.py", line 158, in render
    self.content = self.rendered_content
  File "/home/guinsly/.pyenv/versions/django1.9.3.4.3/lib/python3.4/site-packages/django/template/response.py", line 135, in rendered_content
    content = template.render(context, self._request)
  File "/home/guinsly/.pyenv/versions/django1.9.3.4.3/lib/python3.4/site-packages/django/template/backends/django.py", line 74, in render
    return self.template.render(context)
  File "/home/guinsly/.pyenv/versions/django1.9.3.4.3/lib/python3.4/site-packages/django/template/base.py", line 210, in render
    return self._render(context)
  File "/home/guinsly/.pyenv/versions/django1.9.3.4.3/lib/python3.4/site-packages/django/test/utils.py", line 96, in instrumented_test_render
    return self.nodelist.render(context)
  File "/home/guinsly/.pyenv/versions/django1.9.3.4.3/lib/python3.4/site-packages/django/template/base.py", line 905, in render
    bit = self.render_node(node, context)
  File "/home/guinsly/.pyenv/versions/django1.9.3.4.3/lib/python3.4/site-packages/django/template/debug.py", line 79, in render_node
    return node.render(context)
  File "/home/guinsly/.pyenv/versions/django1.9.3.4.3/lib/python3.4/site-packages/django/template/debug.py", line 89, in render
    output = self.filter_expression.resolve(context)
  File "/home/guinsly/.pyenv/versions/django1.9.3.4.3/lib/python3.4/site-packages/django/template/base.py", line 648, in resolve
    obj = self.var.resolve(context)
  File "/home/guinsly/.pyenv/versions/django1.9.3.4.3/lib/python3.4/site-packages/django/template/base.py", line 789, in resolve
    value = self._resolve_lookup(context)
  File "/home/guinsly/.pyenv/versions/django1.9.3.4.3/lib/python3.4/site-packages/django/template/base.py", line 827, in _resolve_lookup
    current = getattr(current, bit)
  File "/home/guinsly/.pyenv/versions/django1.9.3.4.3/lib/python3.4/site-packages/imagekit/cachefiles/__init__.py", line 84, in url
    return self._storage_attr('url')
  File "/home/guinsly/.pyenv/versions/django1.9.3.4.3/lib/python3.4/site-packages/imagekit/cachefiles/__init__.py", line 74, in _storage_attr
    existence_required.send(sender=self, file=self)
  File "/home/guinsly/.pyenv/versions/django1.9.3.4.3/lib/python3.4/site-packages/django/dispatch/dispatcher.py", line 189, in send
    response = receiver(signal=self, sender=sender, **named)
  File "/home/guinsly/.pyenv/versions/django1.9.3.4.3/lib/python3.4/site-packages/imagekit/registry.py", line 53, in existence_required_receiver
    self._receive(file, 'on_existence_required')
  File "/home/guinsly/.pyenv/versions/django1.9.3.4.3/lib/python3.4/site-packages/imagekit/registry.py", line 61, in _receive
    call_strategy_method(file, callback)
  File "/home/guinsly/.pyenv/versions/django1.9.3.4.3/lib/python3.4/site-packages/imagekit/utils.py", line 151, in call_strategy_method
    fn(file)
  File "/home/guinsly/.pyenv/versions/django1.9.3.4.3/lib/python3.4/site-packages/imagekit/cachefiles/strategies.py", line 15, in on_existence_required
    file.generate()
  File "/home/guinsly/.pyenv/versions/django1.9.3.4.3/lib/python3.4/site-packages/imagekit/cachefiles/__init__.py", line 93, in generate
    self.cachefile_backend.generate(self, force)
  File "/home/guinsly/.pyenv/versions/django1.9.3.4.3/lib/python3.4/site-packages/imagekit/cachefiles/backends.py", line 109, in generate
    self.generate_now(file, force=force)
  File "/home/guinsly/.pyenv/versions/django1.9.3.4.3/lib/python3.4/site-packages/imagekit/cachefiles/backends.py", line 96, in generate_now
    file._generate()
  File "/home/guinsly/.pyenv/versions/django1.9.3.4.3/lib/python3.4/site-packages/imagekit/cachefiles/__init__.py", line 97, in _generate
    content = generate(self.generator)
  File "/home/guinsly/.pyenv/versions/django1.9.3.4.3/lib/python3.4/site-packages/imagekit/utils.py", line 134, in generate
    content = generator.generate()
  File "/home/guinsly/.pyenv/versions/django1.9.3.4.3/lib/python3.4/site-packages/imagekit/specs/__init__.py", line 149, in generate
    img = open_image(self.source)
  File "/home/guinsly/.pyenv/versions/django1.9.3.4.3/lib/python3.4/site-packages/pilkit/utils.py", line 21, in open_image
    target.seek(0)
  File "/home/guinsly/.pyenv/versions/django1.9.3.4.3/lib/python3.4/site-packages/django/core/files/utils.py", line 20, in <lambda>
    seek = property(lambda self: self.file.seek)
  File "/home/guinsly/.pyenv/versions/django1.9.3.4.3/lib/python3.4/site-packages/django/db/models/fields/files.py", line 51, in _get_file
    self._file = self.storage.open(self.name, 'rb')
  File "/home/guinsly/.pyenv/versions/django1.9.3.4.3/lib/python3.4/site-packages/django/core/files/storage.py", line 37, in open
    return self._open(name, mode)
  File "/home/guinsly/.pyenv/versions/django1.9.3.4.3/lib/python3.4/site-packages/django/core/files/storage.py", line 201, in _open
    return File(open(self.path(name), mode))
FileNotFoundError: [Errno 2] No such file or directory: '/home/guinsly/development/public/project/ohmy404/media/404/2016/06/07/Screenshot_from_2016-04-27_095930.png'
ERROR 2016-06-07 21:11:13,309 base.py handle_uncaught_exception 256 Internal Server Error: /
Traceback (most recent call last):
  File "/home/guinsly/.pyenv/versions/django1.9.3.4.3/lib/python3.4/site-packages/django/template/defaulttags.py", line 1159, in load
    lib = get_library(taglib)
  File "/home/guinsly/.pyenv/versions/django1.9.3.4.3/lib/python3.4/site-packages/django/template/base.py", line 1402, in get_library
    ','.join(tried_modules)))
django.template.base.InvalidTemplateLibrary: Template library pipeline not found, tried django.templatetags.pipeline,django.contrib.admin.templatetags.pipeline,django.contrib.staticfiles.templatetags.pipeline,django.contrib.humanize.templatetags.pipeline,django_extensions.templatetags.pipeline,rest_framework.templatetags.pipeline,bootstrap_pagination.templatetags.pipeline,debug_toolbar.templatetags.pipeline,easy_thumbnails.templatetags.pipeline,imagekit.templatetags.pipeline

During handling of the above exception, another exception occurred:

Traceback (most recent call last):
  File "/home/guinsly/.pyenv/versions/django1.9.3.4.3/lib/python3.4/site-packages/django/core/handlers/base.py", line 164, in get_response
    response = response.render()
  File "/home/guinsly/.pyenv/versions/django1.9.3.4.3/lib/python3.4/site-packages/django/template/response.py", line 158, in render
    self.content = self.rendered_content
  File "/home/guinsly/.pyenv/versions/django1.9.3.4.3/lib/python3.4/site-packages/django/template/response.py", line 133, in rendered_content
    template = self._resolve_template(self.template_name)
  File "/home/guinsly/.pyenv/versions/django1.9.3.4.3/lib/python3.4/site-packages/django/template/response.py", line 88, in _resolve_template
    new_template = self.resolve_template(template)
  File "/home/guinsly/.pyenv/versions/django1.9.3.4.3/lib/python3.4/site-packages/django/template/response.py", line 78, in resolve_template
    return loader.select_template(template, using=self.using)
  File "/home/guinsly/.pyenv/versions/django1.9.3.4.3/lib/python3.4/site-packages/django/template/loader.py", line 64, in select_template
    return engine.get_template(template_name, dirs)
  File "/home/guinsly/.pyenv/versions/django1.9.3.4.3/lib/python3.4/site-packages/django/template/backends/django.py", line 30, in get_template
    return Template(self.engine.get_template(template_name, dirs))
  File "/home/guinsly/.pyenv/versions/django1.9.3.4.3/lib/python3.4/site-packages/django/template/engine.py", line 167, in get_template
    template, origin = self.find_template(template_name, dirs)
  File "/home/guinsly/.pyenv/versions/django1.9.3.4.3/lib/python3.4/site-packages/django/template/engine.py", line 141, in find_template
    source, display_name = loader(name, dirs)
  File "/home/guinsly/.pyenv/versions/django1.9.3.4.3/lib/python3.4/site-packages/django/template/loaders/base.py", line 13, in __call__
    return self.load_template(template_name, template_dirs)
  File "/home/guinsly/.pyenv/versions/django1.9.3.4.3/lib/python3.4/site-packages/django/template/loaders/base.py", line 23, in load_template
    template = Template(source, origin, template_name, self.engine)
  File "/home/guinsly/.pyenv/versions/django1.9.3.4.3/lib/python3.4/site-packages/django/template/base.py", line 191, in __init__
    self.nodelist = engine.compile_string(template_string, origin)
  File "/home/guinsly/.pyenv/versions/django1.9.3.4.3/lib/python3.4/site-packages/django/template/engine.py", line 261, in compile_string
    return parser.parse()
  File "/home/guinsly/.pyenv/versions/django1.9.3.4.3/lib/python3.4/site-packages/django/template/base.py", line 342, in parse
    compiled_result = compile_func(self, token)
  File "/home/guinsly/.pyenv/versions/django1.9.3.4.3/lib/python3.4/site-packages/django/template/defaulttags.py", line 1163, in load
    (taglib, e))
django.template.base.TemplateSyntaxError: 'pipeline' is not a valid tag library: Template library pipeline not found, tried django.templatetags.pipeline,django.contrib.admin.templatetags.pipeline,django.contrib.staticfiles.templatetags.pipeline,django.contrib.humanize.templatetags.pipeline,django_extensions.templatetags.pipeline,rest_framework.templatetags.pipeline,bootstrap_pagination.templatetags.pipeline,debug_toolbar.templatetags.pipeline,easy_thumbnails.templatetags.pipeline,imagekit.templatetags.pipeline
ERROR 2016-06-07 21:11:13,309 base.py handle_uncaught_exception 256 Internal Server Error: /
Traceback (most recent call last):
  File "/home/guinsly/.pyenv/versions/django1.9.3.4.3/lib/python3.4/site-packages/django/template/defaulttags.py", line 1159, in load
    lib = get_library(taglib)
  File "/home/guinsly/.pyenv/versions/django1.9.3.4.3/lib/python3.4/site-packages/django/template/base.py", line 1402, in get_library
    ','.join(tried_modules)))
django.template.base.InvalidTemplateLibrary: Template library pipeline not found, tried django.templatetags.pipeline,django.contrib.admin.templatetags.pipeline,django.contrib.staticfiles.templatetags.pipeline,django.contrib.humanize.templatetags.pipeline,django_extensions.templatetags.pipeline,rest_framework.templatetags.pipeline,bootstrap_pagination.templatetags.pipeline,debug_toolbar.templatetags.pipeline,easy_thumbnails.templatetags.pipeline,imagekit.templatetags.pipeline

During handling of the above exception, another exception occurred:

Traceback (most recent call last):
  File "/home/guinsly/.pyenv/versions/django1.9.3.4.3/lib/python3.4/site-packages/django/core/handlers/base.py", line 164, in get_response
    response = response.render()
  File "/home/guinsly/.pyenv/versions/django1.9.3.4.3/lib/python3.4/site-packages/django/template/response.py", line 158, in render
    self.content = self.rendered_content
  File "/home/guinsly/.pyenv/versions/django1.9.3.4.3/lib/python3.4/site-packages/django/template/response.py", line 133, in rendered_content
    template = self._resolve_template(self.template_name)
  File "/home/guinsly/.pyenv/versions/django1.9.3.4.3/lib/python3.4/site-packages/django/template/response.py", line 88, in _resolve_template
    new_template = self.resolve_template(template)
  File "/home/guinsly/.pyenv/versions/django1.9.3.4.3/lib/python3.4/site-packages/django/template/response.py", line 78, in resolve_template
    return loader.select_template(template, using=self.using)
  File "/home/guinsly/.pyenv/versions/django1.9.3.4.3/lib/python3.4/site-packages/django/template/loader.py", line 64, in select_template
    return engine.get_template(template_name, dirs)
  File "/home/guinsly/.pyenv/versions/django1.9.3.4.3/lib/python3.4/site-packages/django/template/backends/django.py", line 30, in get_template
    return Template(self.engine.get_template(template_name, dirs))
  File "/home/guinsly/.pyenv/versions/django1.9.3.4.3/lib/python3.4/site-packages/django/template/engine.py", line 167, in get_template
    template, origin = self.find_template(template_name, dirs)
  File "/home/guinsly/.pyenv/versions/django1.9.3.4.3/lib/python3.4/site-packages/django/template/engine.py", line 141, in find_template
    source, display_name = loader(name, dirs)
  File "/home/guinsly/.pyenv/versions/django1.9.3.4.3/lib/python3.4/site-packages/django/template/loaders/base.py", line 13, in __call__
    return self.load_template(template_name, template_dirs)
  File "/home/guinsly/.pyenv/versions/django1.9.3.4.3/lib/python3.4/site-packages/django/template/loaders/base.py", line 23, in load_template
    template = Template(source, origin, template_name, self.engine)
  File "/home/guinsly/.pyenv/versions/django1.9.3.4.3/lib/python3.4/site-packages/django/template/base.py", line 191, in __init__
    self.nodelist = engine.compile_string(template_string, origin)
  File "/home/guinsly/.pyenv/versions/django1.9.3.4.3/lib/python3.4/site-packages/django/template/engine.py", line 261, in compile_string
    return parser.parse()
  File "/home/guinsly/.pyenv/versions/django1.9.3.4.3/lib/python3.4/site-packages/django/template/base.py", line 342, in parse
    compiled_result = compile_func(self, token)
  File "/home/guinsly/.pyenv/versions/django1.9.3.4.3/lib/python3.4/site-packages/django/template/defaulttags.py", line 1163, in load
    (taglib, e))
django.template.base.TemplateSyntaxError: 'pipeline' is not a valid tag library: Template library pipeline not found, tried django.templatetags.pipeline,django.contrib.admin.templatetags.pipeline,django.contrib.staticfiles.templatetags.pipeline,django.contrib.humanize.templatetags.pipeline,django_extensions.templatetags.pipeline,rest_framework.templatetags.pipeline,bootstrap_pagination.templatetags.pipeline,debug_toolbar.templatetags.pipeline,easy_thumbnails.templatetags.pipeline,imagekit.templatetags.pipeline
ERROR 2016-06-07 21:11:13,309 base.py handle_uncaught_exception 256 Internal Server Error: /
Traceback (most recent call last):
  File "/home/guinsly/.pyenv/versions/django1.9.3.4.3/lib/python3.4/site-packages/django/template/defaulttags.py", line 1159, in load
    lib = get_library(taglib)
  File "/home/guinsly/.pyenv/versions/django1.9.3.4.3/lib/python3.4/site-packages/django/template/base.py", line 1402, in get_library
    ','.join(tried_modules)))
django.template.base.InvalidTemplateLibrary: Template library pipeline not found, tried django.templatetags.pipeline,django.contrib.admin.templatetags.pipeline,django.contrib.staticfiles.templatetags.pipeline,django.contrib.humanize.templatetags.pipeline,django_extensions.templatetags.pipeline,rest_framework.templatetags.pipeline,bootstrap_pagination.templatetags.pipeline,debug_toolbar.templatetags.pipeline,easy_thumbnails.templatetags.pipeline,imagekit.templatetags.pipeline

During handling of the above exception, another exception occurred:

Traceback (most recent call last):
  File "/home/guinsly/.pyenv/versions/django1.9.3.4.3/lib/python3.4/site-packages/django/core/handlers/base.py", line 164, in get_response
    response = response.render()
  File "/home/guinsly/.pyenv/versions/django1.9.3.4.3/lib/python3.4/site-packages/django/template/response.py", line 158, in render
    self.content = self.rendered_content
  File "/home/guinsly/.pyenv/versions/django1.9.3.4.3/lib/python3.4/site-packages/django/template/response.py", line 133, in rendered_content
    template = self._resolve_template(self.template_name)
  File "/home/guinsly/.pyenv/versions/django1.9.3.4.3/lib/python3.4/site-packages/django/template/response.py", line 88, in _resolve_template
    new_template = self.resolve_template(template)
  File "/home/guinsly/.pyenv/versions/django1.9.3.4.3/lib/python3.4/site-packages/django/template/response.py", line 78, in resolve_template
    return loader.select_template(template, using=self.using)
  File "/home/guinsly/.pyenv/versions/django1.9.3.4.3/lib/python3.4/site-packages/django/template/loader.py", line 64, in select_template
    return engine.get_template(template_name, dirs)
  File "/home/guinsly/.pyenv/versions/django1.9.3.4.3/lib/python3.4/site-packages/django/template/backends/django.py", line 30, in get_template
    return Template(self.engine.get_template(template_name, dirs))
  File "/home/guinsly/.pyenv/versions/django1.9.3.4.3/lib/python3.4/site-packages/django/template/engine.py", line 167, in get_template
    template, origin = self.find_template(template_name, dirs)
  File "/home/guinsly/.pyenv/versions/django1.9.3.4.3/lib/python3.4/site-packages/django/template/engine.py", line 141, in find_template
    source, display_name = loader(name, dirs)
  File "/home/guinsly/.pyenv/versions/django1.9.3.4.3/lib/python3.4/site-packages/django/template/loaders/base.py", line 13, in __call__
    return self.load_template(template_name, template_dirs)
  File "/home/guinsly/.pyenv/versions/django1.9.3.4.3/lib/python3.4/site-packages/django/template/loaders/base.py", line 23, in load_template
    template = Template(source, origin, template_name, self.engine)
  File "/home/guinsly/.pyenv/versions/django1.9.3.4.3/lib/python3.4/site-packages/django/template/base.py", line 191, in __init__
    self.nodelist = engine.compile_string(template_string, origin)
  File "/home/guinsly/.pyenv/versions/django1.9.3.4.3/lib/python3.4/site-packages/django/template/engine.py", line 261, in compile_string
    return parser.parse()
  File "/home/guinsly/.pyenv/versions/django1.9.3.4.3/lib/python3.4/site-packages/django/template/base.py", line 342, in parse
    compiled_result = compile_func(self, token)
  File "/home/guinsly/.pyenv/versions/django1.9.3.4.3/lib/python3.4/site-packages/django/template/defaulttags.py", line 1163, in load
    (taglib, e))
django.template.base.TemplateSyntaxError: 'pipeline' is not a valid tag library: Template library pipeline not found, tried django.templatetags.pipeline,django.contrib.admin.templatetags.pipeline,django.contrib.staticfiles.templatetags.pipeline,django.contrib.humanize.templatetags.pipeline,django_extensions.templatetags.pipeline,rest_framework.templatetags.pipeline,bootstrap_pagination.templatetags.pipeline,debug_toolbar.templatetags.pipeline,easy_thumbnails.templatetags.pipeline,imagekit.templatetags.pipeline
ERROR 2016-06-07 21:11:34,054 base.py handle_uncaught_exception 256 Internal Server Error: /
Traceback (most recent call last):
  File "/home/guinsly/.pyenv/versions/django1.9.3.4.3/lib/python3.4/site-packages/django/template/defaulttags.py", line 1159, in load
    lib = get_library(taglib)
  File "/home/guinsly/.pyenv/versions/django1.9.3.4.3/lib/python3.4/site-packages/django/template/base.py", line 1402, in get_library
    ','.join(tried_modules)))
django.template.base.InvalidTemplateLibrary: Template library pipeline not found, tried django.templatetags.pipeline,django.contrib.admin.templatetags.pipeline,django.contrib.staticfiles.templatetags.pipeline,django.contrib.humanize.templatetags.pipeline,django_extensions.templatetags.pipeline,rest_framework.templatetags.pipeline,bootstrap_pagination.templatetags.pipeline,debug_toolbar.templatetags.pipeline,easy_thumbnails.templatetags.pipeline,imagekit.templatetags.pipeline

During handling of the above exception, another exception occurred:

Traceback (most recent call last):
  File "/home/guinsly/.pyenv/versions/django1.9.3.4.3/lib/python3.4/site-packages/django/core/handlers/base.py", line 164, in get_response
    response = response.render()
  File "/home/guinsly/.pyenv/versions/django1.9.3.4.3/lib/python3.4/site-packages/django/template/response.py", line 158, in render
    self.content = self.rendered_content
  File "/home/guinsly/.pyenv/versions/django1.9.3.4.3/lib/python3.4/site-packages/django/template/response.py", line 133, in rendered_content
    template = self._resolve_template(self.template_name)
  File "/home/guinsly/.pyenv/versions/django1.9.3.4.3/lib/python3.4/site-packages/django/template/response.py", line 88, in _resolve_template
    new_template = self.resolve_template(template)
  File "/home/guinsly/.pyenv/versions/django1.9.3.4.3/lib/python3.4/site-packages/django/template/response.py", line 78, in resolve_template
    return loader.select_template(template, using=self.using)
  File "/home/guinsly/.pyenv/versions/django1.9.3.4.3/lib/python3.4/site-packages/django/template/loader.py", line 64, in select_template
    return engine.get_template(template_name, dirs)
  File "/home/guinsly/.pyenv/versions/django1.9.3.4.3/lib/python3.4/site-packages/django/template/backends/django.py", line 30, in get_template
    return Template(self.engine.get_template(template_name, dirs))
  File "/home/guinsly/.pyenv/versions/django1.9.3.4.3/lib/python3.4/site-packages/django/template/engine.py", line 167, in get_template
    template, origin = self.find_template(template_name, dirs)
  File "/home/guinsly/.pyenv/versions/django1.9.3.4.3/lib/python3.4/site-packages/django/template/engine.py", line 141, in find_template
    source, display_name = loader(name, dirs)
  File "/home/guinsly/.pyenv/versions/django1.9.3.4.3/lib/python3.4/site-packages/django/template/loaders/base.py", line 13, in __call__
    return self.load_template(template_name, template_dirs)
  File "/home/guinsly/.pyenv/versions/django1.9.3.4.3/lib/python3.4/site-packages/django/template/loaders/base.py", line 23, in load_template
    template = Template(source, origin, template_name, self.engine)
  File "/home/guinsly/.pyenv/versions/django1.9.3.4.3/lib/python3.4/site-packages/django/template/base.py", line 191, in __init__
    self.nodelist = engine.compile_string(template_string, origin)
  File "/home/guinsly/.pyenv/versions/django1.9.3.4.3/lib/python3.4/site-packages/django/template/engine.py", line 261, in compile_string
    return parser.parse()
  File "/home/guinsly/.pyenv/versions/django1.9.3.4.3/lib/python3.4/site-packages/django/template/base.py", line 342, in parse
    compiled_result = compile_func(self, token)
  File "/home/guinsly/.pyenv/versions/django1.9.3.4.3/lib/python3.4/site-packages/django/template/defaulttags.py", line 1163, in load
    (taglib, e))
django.template.base.TemplateSyntaxError: 'pipeline' is not a valid tag library: Template library pipeline not found, tried django.templatetags.pipeline,django.contrib.admin.templatetags.pipeline,django.contrib.staticfiles.templatetags.pipeline,django.contrib.humanize.templatetags.pipeline,django_extensions.templatetags.pipeline,rest_framework.templatetags.pipeline,bootstrap_pagination.templatetags.pipeline,debug_toolbar.templatetags.pipeline,easy_thumbnails.templatetags.pipeline,imagekit.templatetags.pipeline
ERROR 2016-06-07 21:11:34,054 base.py handle_uncaught_exception 256 Internal Server Error: /
Traceback (most recent call last):
  File "/home/guinsly/.pyenv/versions/django1.9.3.4.3/lib/python3.4/site-packages/django/template/defaulttags.py", line 1159, in load
    lib = get_library(taglib)
  File "/home/guinsly/.pyenv/versions/django1.9.3.4.3/lib/python3.4/site-packages/django/template/base.py", line 1402, in get_library
    ','.join(tried_modules)))
django.template.base.InvalidTemplateLibrary: Template library pipeline not found, tried django.templatetags.pipeline,django.contrib.admin.templatetags.pipeline,django.contrib.staticfiles.templatetags.pipeline,django.contrib.humanize.templatetags.pipeline,django_extensions.templatetags.pipeline,rest_framework.templatetags.pipeline,bootstrap_pagination.templatetags.pipeline,debug_toolbar.templatetags.pipeline,easy_thumbnails.templatetags.pipeline,imagekit.templatetags.pipeline

During handling of the above exception, another exception occurred:

Traceback (most recent call last):
  File "/home/guinsly/.pyenv/versions/django1.9.3.4.3/lib/python3.4/site-packages/django/core/handlers/base.py", line 164, in get_response
    response = response.render()
  File "/home/guinsly/.pyenv/versions/django1.9.3.4.3/lib/python3.4/site-packages/django/template/response.py", line 158, in render
    self.content = self.rendered_content
  File "/home/guinsly/.pyenv/versions/django1.9.3.4.3/lib/python3.4/site-packages/django/template/response.py", line 133, in rendered_content
    template = self._resolve_template(self.template_name)
  File "/home/guinsly/.pyenv/versions/django1.9.3.4.3/lib/python3.4/site-packages/django/template/response.py", line 88, in _resolve_template
    new_template = self.resolve_template(template)
  File "/home/guinsly/.pyenv/versions/django1.9.3.4.3/lib/python3.4/site-packages/django/template/response.py", line 78, in resolve_template
    return loader.select_template(template, using=self.using)
  File "/home/guinsly/.pyenv/versions/django1.9.3.4.3/lib/python3.4/site-packages/django/template/loader.py", line 64, in select_template
    return engine.get_template(template_name, dirs)
  File "/home/guinsly/.pyenv/versions/django1.9.3.4.3/lib/python3.4/site-packages/django/template/backends/django.py", line 30, in get_template
    return Template(self.engine.get_template(template_name, dirs))
  File "/home/guinsly/.pyenv/versions/django1.9.3.4.3/lib/python3.4/site-packages/django/template/engine.py", line 167, in get_template
    template, origin = self.find_template(template_name, dirs)
  File "/home/guinsly/.pyenv/versions/django1.9.3.4.3/lib/python3.4/site-packages/django/template/engine.py", line 141, in find_template
    source, display_name = loader(name, dirs)
  File "/home/guinsly/.pyenv/versions/django1.9.3.4.3/lib/python3.4/site-packages/django/template/loaders/base.py", line 13, in __call__
    return self.load_template(template_name, template_dirs)
  File "/home/guinsly/.pyenv/versions/django1.9.3.4.3/lib/python3.4/site-packages/django/template/loaders/base.py", line 23, in load_template
    template = Template(source, origin, template_name, self.engine)
  File "/home/guinsly/.pyenv/versions/django1.9.3.4.3/lib/python3.4/site-packages/django/template/base.py", line 191, in __init__
    self.nodelist = engine.compile_string(template_string, origin)
  File "/home/guinsly/.pyenv/versions/django1.9.3.4.3/lib/python3.4/site-packages/django/template/engine.py", line 261, in compile_string
    return parser.parse()
  File "/home/guinsly/.pyenv/versions/django1.9.3.4.3/lib/python3.4/site-packages/django/template/base.py", line 342, in parse
    compiled_result = compile_func(self, token)
  File "/home/guinsly/.pyenv/versions/django1.9.3.4.3/lib/python3.4/site-packages/django/template/defaulttags.py", line 1163, in load
    (taglib, e))
django.template.base.TemplateSyntaxError: 'pipeline' is not a valid tag library: Template library pipeline not found, tried django.templatetags.pipeline,django.contrib.admin.templatetags.pipeline,django.contrib.staticfiles.templatetags.pipeline,django.contrib.humanize.templatetags.pipeline,django_extensions.templatetags.pipeline,rest_framework.templatetags.pipeline,bootstrap_pagination.templatetags.pipeline,debug_toolbar.templatetags.pipeline,easy_thumbnails.templatetags.pipeline,imagekit.templatetags.pipeline
ERROR 2016-06-07 21:11:34,054 base.py handle_uncaught_exception 256 Internal Server Error: /
Traceback (most recent call last):
  File "/home/guinsly/.pyenv/versions/django1.9.3.4.3/lib/python3.4/site-packages/django/template/defaulttags.py", line 1159, in load
    lib = get_library(taglib)
  File "/home/guinsly/.pyenv/versions/django1.9.3.4.3/lib/python3.4/site-packages/django/template/base.py", line 1402, in get_library
    ','.join(tried_modules)))
django.template.base.InvalidTemplateLibrary: Template library pipeline not found, tried django.templatetags.pipeline,django.contrib.admin.templatetags.pipeline,django.contrib.staticfiles.templatetags.pipeline,django.contrib.humanize.templatetags.pipeline,django_extensions.templatetags.pipeline,rest_framework.templatetags.pipeline,bootstrap_pagination.templatetags.pipeline,debug_toolbar.templatetags.pipeline,easy_thumbnails.templatetags.pipeline,imagekit.templatetags.pipeline

During handling of the above exception, another exception occurred:

Traceback (most recent call last):
  File "/home/guinsly/.pyenv/versions/django1.9.3.4.3/lib/python3.4/site-packages/django/core/handlers/base.py", line 164, in get_response
    response = response.render()
  File "/home/guinsly/.pyenv/versions/django1.9.3.4.3/lib/python3.4/site-packages/django/template/response.py", line 158, in render
    self.content = self.rendered_content
  File "/home/guinsly/.pyenv/versions/django1.9.3.4.3/lib/python3.4/site-packages/django/template/response.py", line 133, in rendered_content
    template = self._resolve_template(self.template_name)
  File "/home/guinsly/.pyenv/versions/django1.9.3.4.3/lib/python3.4/site-packages/django/template/response.py", line 88, in _resolve_template
    new_template = self.resolve_template(template)
  File "/home/guinsly/.pyenv/versions/django1.9.3.4.3/lib/python3.4/site-packages/django/template/response.py", line 78, in resolve_template
    return loader.select_template(template, using=self.using)
  File "/home/guinsly/.pyenv/versions/django1.9.3.4.3/lib/python3.4/site-packages/django/template/loader.py", line 64, in select_template
    return engine.get_template(template_name, dirs)
  File "/home/guinsly/.pyenv/versions/django1.9.3.4.3/lib/python3.4/site-packages/django/template/backends/django.py", line 30, in get_template
    return Template(self.engine.get_template(template_name, dirs))
  File "/home/guinsly/.pyenv/versions/django1.9.3.4.3/lib/python3.4/site-packages/django/template/engine.py", line 167, in get_template
    template, origin = self.find_template(template_name, dirs)
  File "/home/guinsly/.pyenv/versions/django1.9.3.4.3/lib/python3.4/site-packages/django/template/engine.py", line 141, in find_template
    source, display_name = loader(name, dirs)
  File "/home/guinsly/.pyenv/versions/django1.9.3.4.3/lib/python3.4/site-packages/django/template/loaders/base.py", line 13, in __call__
    return self.load_template(template_name, template_dirs)
  File "/home/guinsly/.pyenv/versions/django1.9.3.4.3/lib/python3.4/site-packages/django/template/loaders/base.py", line 23, in load_template
    template = Template(source, origin, template_name, self.engine)
  File "/home/guinsly/.pyenv/versions/django1.9.3.4.3/lib/python3.4/site-packages/django/template/base.py", line 191, in __init__
    self.nodelist = engine.compile_string(template_string, origin)
  File "/home/guinsly/.pyenv/versions/django1.9.3.4.3/lib/python3.4/site-packages/django/template/engine.py", line 261, in compile_string
    return parser.parse()
  File "/home/guinsly/.pyenv/versions/django1.9.3.4.3/lib/python3.4/site-packages/django/template/base.py", line 342, in parse
    compiled_result = compile_func(self, token)
  File "/home/guinsly/.pyenv/versions/django1.9.3.4.3/lib/python3.4/site-packages/django/template/defaulttags.py", line 1163, in load
    (taglib, e))
django.template.base.TemplateSyntaxError: 'pipeline' is not a valid tag library: Template library pipeline not found, tried django.templatetags.pipeline,django.contrib.admin.templatetags.pipeline,django.contrib.staticfiles.templatetags.pipeline,django.contrib.humanize.templatetags.pipeline,django_extensions.templatetags.pipeline,rest_framework.templatetags.pipeline,bootstrap_pagination.templatetags.pipeline,debug_toolbar.templatetags.pipeline,easy_thumbnails.templatetags.pipeline,imagekit.templatetags.pipeline
ERROR 2016-06-07 21:29:08,916 base.py handle_uncaught_exception 256 Internal Server Error: /
Traceback (most recent call last):
  File "/home/guinsly/.pyenv/versions/django1.9.3.4.3/lib/python3.4/site-packages/django/template/defaulttags.py", line 1159, in load
    lib = get_library(taglib)
  File "/home/guinsly/.pyenv/versions/django1.9.3.4.3/lib/python3.4/site-packages/django/template/base.py", line 1402, in get_library
    ','.join(tried_modules)))
django.template.base.InvalidTemplateLibrary: Template library pipeline not found, tried django.templatetags.pipeline,django.contrib.admin.templatetags.pipeline,django.contrib.staticfiles.templatetags.pipeline,django.contrib.humanize.templatetags.pipeline,django_extensions.templatetags.pipeline,rest_framework.templatetags.pipeline,bootstrap_pagination.templatetags.pipeline,debug_toolbar.templatetags.pipeline,easy_thumbnails.templatetags.pipeline,imagekit.templatetags.pipeline

During handling of the above exception, another exception occurred:

Traceback (most recent call last):
  File "/home/guinsly/.pyenv/versions/django1.9.3.4.3/lib/python3.4/site-packages/django/core/handlers/base.py", line 164, in get_response
    response = response.render()
  File "/home/guinsly/.pyenv/versions/django1.9.3.4.3/lib/python3.4/site-packages/django/template/response.py", line 158, in render
    self.content = self.rendered_content
  File "/home/guinsly/.pyenv/versions/django1.9.3.4.3/lib/python3.4/site-packages/django/template/response.py", line 133, in rendered_content
    template = self._resolve_template(self.template_name)
  File "/home/guinsly/.pyenv/versions/django1.9.3.4.3/lib/python3.4/site-packages/django/template/response.py", line 88, in _resolve_template
    new_template = self.resolve_template(template)
  File "/home/guinsly/.pyenv/versions/django1.9.3.4.3/lib/python3.4/site-packages/django/template/response.py", line 78, in resolve_template
    return loader.select_template(template, using=self.using)
  File "/home/guinsly/.pyenv/versions/django1.9.3.4.3/lib/python3.4/site-packages/django/template/loader.py", line 64, in select_template
    return engine.get_template(template_name, dirs)
  File "/home/guinsly/.pyenv/versions/django1.9.3.4.3/lib/python3.4/site-packages/django/template/backends/django.py", line 30, in get_template
    return Template(self.engine.get_template(template_name, dirs))
  File "/home/guinsly/.pyenv/versions/django1.9.3.4.3/lib/python3.4/site-packages/django/template/engine.py", line 167, in get_template
    template, origin = self.find_template(template_name, dirs)
  File "/home/guinsly/.pyenv/versions/django1.9.3.4.3/lib/python3.4/site-packages/django/template/engine.py", line 141, in find_template
    source, display_name = loader(name, dirs)
  File "/home/guinsly/.pyenv/versions/django1.9.3.4.3/lib/python3.4/site-packages/django/template/loaders/base.py", line 13, in __call__
    return self.load_template(template_name, template_dirs)
  File "/home/guinsly/.pyenv/versions/django1.9.3.4.3/lib/python3.4/site-packages/django/template/loaders/base.py", line 23, in load_template
    template = Template(source, origin, template_name, self.engine)
  File "/home/guinsly/.pyenv/versions/django1.9.3.4.3/lib/python3.4/site-packages/django/template/base.py", line 191, in __init__
    self.nodelist = engine.compile_string(template_string, origin)
  File "/home/guinsly/.pyenv/versions/django1.9.3.4.3/lib/python3.4/site-packages/django/template/engine.py", line 261, in compile_string
    return parser.parse()
  File "/home/guinsly/.pyenv/versions/django1.9.3.4.3/lib/python3.4/site-packages/django/template/base.py", line 342, in parse
    compiled_result = compile_func(self, token)
  File "/home/guinsly/.pyenv/versions/django1.9.3.4.3/lib/python3.4/site-packages/django/template/defaulttags.py", line 1163, in load
    (taglib, e))
django.template.base.TemplateSyntaxError: 'pipeline' is not a valid tag library: Template library pipeline not found, tried django.templatetags.pipeline,django.contrib.admin.templatetags.pipeline,django.contrib.staticfiles.templatetags.pipeline,django.contrib.humanize.templatetags.pipeline,django_extensions.templatetags.pipeline,rest_framework.templatetags.pipeline,bootstrap_pagination.templatetags.pipeline,debug_toolbar.templatetags.pipeline,easy_thumbnails.templatetags.pipeline,imagekit.templatetags.pipeline
ERROR 2016-06-07 21:29:08,916 base.py handle_uncaught_exception 256 Internal Server Error: /
Traceback (most recent call last):
  File "/home/guinsly/.pyenv/versions/django1.9.3.4.3/lib/python3.4/site-packages/django/template/defaulttags.py", line 1159, in load
    lib = get_library(taglib)
  File "/home/guinsly/.pyenv/versions/django1.9.3.4.3/lib/python3.4/site-packages/django/template/base.py", line 1402, in get_library
    ','.join(tried_modules)))
django.template.base.InvalidTemplateLibrary: Template library pipeline not found, tried django.templatetags.pipeline,django.contrib.admin.templatetags.pipeline,django.contrib.staticfiles.templatetags.pipeline,django.contrib.humanize.templatetags.pipeline,django_extensions.templatetags.pipeline,rest_framework.templatetags.pipeline,bootstrap_pagination.templatetags.pipeline,debug_toolbar.templatetags.pipeline,easy_thumbnails.templatetags.pipeline,imagekit.templatetags.pipeline

During handling of the above exception, another exception occurred:

Traceback (most recent call last):
  File "/home/guinsly/.pyenv/versions/django1.9.3.4.3/lib/python3.4/site-packages/django/core/handlers/base.py", line 164, in get_response
    response = response.render()
  File "/home/guinsly/.pyenv/versions/django1.9.3.4.3/lib/python3.4/site-packages/django/template/response.py", line 158, in render
    self.content = self.rendered_content
  File "/home/guinsly/.pyenv/versions/django1.9.3.4.3/lib/python3.4/site-packages/django/template/response.py", line 133, in rendered_content
    template = self._resolve_template(self.template_name)
  File "/home/guinsly/.pyenv/versions/django1.9.3.4.3/lib/python3.4/site-packages/django/template/response.py", line 88, in _resolve_template
    new_template = self.resolve_template(template)
  File "/home/guinsly/.pyenv/versions/django1.9.3.4.3/lib/python3.4/site-packages/django/template/response.py", line 78, in resolve_template
    return loader.select_template(template, using=self.using)
  File "/home/guinsly/.pyenv/versions/django1.9.3.4.3/lib/python3.4/site-packages/django/template/loader.py", line 64, in select_template
    return engine.get_template(template_name, dirs)
  File "/home/guinsly/.pyenv/versions/django1.9.3.4.3/lib/python3.4/site-packages/django/template/backends/django.py", line 30, in get_template
    return Template(self.engine.get_template(template_name, dirs))
  File "/home/guinsly/.pyenv/versions/django1.9.3.4.3/lib/python3.4/site-packages/django/template/engine.py", line 167, in get_template
    template, origin = self.find_template(template_name, dirs)
  File "/home/guinsly/.pyenv/versions/django1.9.3.4.3/lib/python3.4/site-packages/django/template/engine.py", line 141, in find_template
    source, display_name = loader(name, dirs)
  File "/home/guinsly/.pyenv/versions/django1.9.3.4.3/lib/python3.4/site-packages/django/template/loaders/base.py", line 13, in __call__
    return self.load_template(template_name, template_dirs)
  File "/home/guinsly/.pyenv/versions/django1.9.3.4.3/lib/python3.4/site-packages/django/template/loaders/base.py", line 23, in load_template
    template = Template(source, origin, template_name, self.engine)
  File "/home/guinsly/.pyenv/versions/django1.9.3.4.3/lib/python3.4/site-packages/django/template/base.py", line 191, in __init__
    self.nodelist = engine.compile_string(template_string, origin)
  File "/home/guinsly/.pyenv/versions/django1.9.3.4.3/lib/python3.4/site-packages/django/template/engine.py", line 261, in compile_string
    return parser.parse()
  File "/home/guinsly/.pyenv/versions/django1.9.3.4.3/lib/python3.4/site-packages/django/template/base.py", line 342, in parse
    compiled_result = compile_func(self, token)
  File "/home/guinsly/.pyenv/versions/django1.9.3.4.3/lib/python3.4/site-packages/django/template/defaulttags.py", line 1163, in load
    (taglib, e))
django.template.base.TemplateSyntaxError: 'pipeline' is not a valid tag library: Template library pipeline not found, tried django.templatetags.pipeline,django.contrib.admin.templatetags.pipeline,django.contrib.staticfiles.templatetags.pipeline,django.contrib.humanize.templatetags.pipeline,django_extensions.templatetags.pipeline,rest_framework.templatetags.pipeline,bootstrap_pagination.templatetags.pipeline,debug_toolbar.templatetags.pipeline,easy_thumbnails.templatetags.pipeline,imagekit.templatetags.pipeline
ERROR 2016-06-07 21:29:08,916 base.py handle_uncaught_exception 256 Internal Server Error: /
Traceback (most recent call last):
  File "/home/guinsly/.pyenv/versions/django1.9.3.4.3/lib/python3.4/site-packages/django/template/defaulttags.py", line 1159, in load
    lib = get_library(taglib)
  File "/home/guinsly/.pyenv/versions/django1.9.3.4.3/lib/python3.4/site-packages/django/template/base.py", line 1402, in get_library
    ','.join(tried_modules)))
django.template.base.InvalidTemplateLibrary: Template library pipeline not found, tried django.templatetags.pipeline,django.contrib.admin.templatetags.pipeline,django.contrib.staticfiles.templatetags.pipeline,django.contrib.humanize.templatetags.pipeline,django_extensions.templatetags.pipeline,rest_framework.templatetags.pipeline,bootstrap_pagination.templatetags.pipeline,debug_toolbar.templatetags.pipeline,easy_thumbnails.templatetags.pipeline,imagekit.templatetags.pipeline

During handling of the above exception, another exception occurred:

Traceback (most recent call last):
  File "/home/guinsly/.pyenv/versions/django1.9.3.4.3/lib/python3.4/site-packages/django/core/handlers/base.py", line 164, in get_response
    response = response.render()
  File "/home/guinsly/.pyenv/versions/django1.9.3.4.3/lib/python3.4/site-packages/django/template/response.py", line 158, in render
    self.content = self.rendered_content
  File "/home/guinsly/.pyenv/versions/django1.9.3.4.3/lib/python3.4/site-packages/django/template/response.py", line 133, in rendered_content
    template = self._resolve_template(self.template_name)
  File "/home/guinsly/.pyenv/versions/django1.9.3.4.3/lib/python3.4/site-packages/django/template/response.py", line 88, in _resolve_template
    new_template = self.resolve_template(template)
  File "/home/guinsly/.pyenv/versions/django1.9.3.4.3/lib/python3.4/site-packages/django/template/response.py", line 78, in resolve_template
    return loader.select_template(template, using=self.using)
  File "/home/guinsly/.pyenv/versions/django1.9.3.4.3/lib/python3.4/site-packages/django/template/loader.py", line 64, in select_template
    return engine.get_template(template_name, dirs)
  File "/home/guinsly/.pyenv/versions/django1.9.3.4.3/lib/python3.4/site-packages/django/template/backends/django.py", line 30, in get_template
    return Template(self.engine.get_template(template_name, dirs))
  File "/home/guinsly/.pyenv/versions/django1.9.3.4.3/lib/python3.4/site-packages/django/template/engine.py", line 167, in get_template
    template, origin = self.find_template(template_name, dirs)
  File "/home/guinsly/.pyenv/versions/django1.9.3.4.3/lib/python3.4/site-packages/django/template/engine.py", line 141, in find_template
    source, display_name = loader(name, dirs)
  File "/home/guinsly/.pyenv/versions/django1.9.3.4.3/lib/python3.4/site-packages/django/template/loaders/base.py", line 13, in __call__
    return self.load_template(template_name, template_dirs)
  File "/home/guinsly/.pyenv/versions/django1.9.3.4.3/lib/python3.4/site-packages/django/template/loaders/base.py", line 23, in load_template
    template = Template(source, origin, template_name, self.engine)
  File "/home/guinsly/.pyenv/versions/django1.9.3.4.3/lib/python3.4/site-packages/django/template/base.py", line 191, in __init__
    self.nodelist = engine.compile_string(template_string, origin)
  File "/home/guinsly/.pyenv/versions/django1.9.3.4.3/lib/python3.4/site-packages/django/template/engine.py", line 261, in compile_string
    return parser.parse()
  File "/home/guinsly/.pyenv/versions/django1.9.3.4.3/lib/python3.4/site-packages/django/template/base.py", line 342, in parse
    compiled_result = compile_func(self, token)
  File "/home/guinsly/.pyenv/versions/django1.9.3.4.3/lib/python3.4/site-packages/django/template/defaulttags.py", line 1163, in load
    (taglib, e))
django.template.base.TemplateSyntaxError: 'pipeline' is not a valid tag library: Template library pipeline not found, tried django.templatetags.pipeline,django.contrib.admin.templatetags.pipeline,django.contrib.staticfiles.templatetags.pipeline,django.contrib.humanize.templatetags.pipeline,django_extensions.templatetags.pipeline,rest_framework.templatetags.pipeline,bootstrap_pagination.templatetags.pipeline,debug_toolbar.templatetags.pipeline,easy_thumbnails.templatetags.pipeline,imagekit.templatetags.pipeline
