ERROR 2016-06-07 18:49:24,584 base.py handle_uncaught_exception 256 Internal Server Error: /admin/login/
Traceback (most recent call last):
  File "/home/guinsly/.pyenv/versions/django1.9.3.4.3/lib/python3.4/site-packages/django/core/handlers/base.py", line 132, in get_response
    response = wrapped_callback(request, *callback_args, **callback_kwargs)
  File "/home/guinsly/.pyenv/versions/django1.9.3.4.3/lib/python3.4/site-packages/django/views/decorators/cache.py", line 57, in _wrapped_view_func
    response = view_func(request, *args, **kwargs)
  File "/home/guinsly/.pyenv/versions/django1.9.3.4.3/lib/python3.4/site-packages/django/contrib/admin/sites.py", line 400, in login
    return login(request, **defaults)
  File "/home/guinsly/.pyenv/versions/django1.9.3.4.3/lib/python3.4/site-packages/django/views/decorators/debug.py", line 76, in sensitive_post_parameters_wrapper
    return view(request, *args, **kwargs)
  File "/home/guinsly/.pyenv/versions/django1.9.3.4.3/lib/python3.4/site-packages/django/utils/decorators.py", line 110, in _wrapped_view
    response = view_func(request, *args, **kwargs)
  File "/home/guinsly/.pyenv/versions/django1.9.3.4.3/lib/python3.4/site-packages/django/views/decorators/cache.py", line 57, in _wrapped_view_func
    response = view_func(request, *args, **kwargs)
  File "/home/guinsly/.pyenv/versions/django1.9.3.4.3/lib/python3.4/site-packages/django/contrib/auth/views.py", line 57, in login
    current_site = get_current_site(request)
  File "/home/guinsly/.pyenv/versions/django1.9.3.4.3/lib/python3.4/site-packages/django/contrib/sites/shortcuts.py", line 15, in get_current_site
    return Site.objects.get_current(request)
  File "/home/guinsly/.pyenv/versions/django1.9.3.4.3/lib/python3.4/site-packages/django/contrib/sites/models.py", line 62, in get_current
    return self._get_site_by_request(request)
  File "/home/guinsly/.pyenv/versions/django1.9.3.4.3/lib/python3.4/site-packages/django/contrib/sites/models.py", line 46, in _get_site_by_request
    site = self.get(domain__iexact=host)
  File "/home/guinsly/.pyenv/versions/django1.9.3.4.3/lib/python3.4/site-packages/django/db/models/manager.py", line 127, in manager_method
    return getattr(self.get_queryset(), name)(*args, **kwargs)
  File "/home/guinsly/.pyenv/versions/django1.9.3.4.3/lib/python3.4/site-packages/django/db/models/query.py", line 334, in get
    self.model._meta.object_name
django.contrib.sites.models.DoesNotExist: Site matching query does not exist.
ERROR 2016-06-07 18:49:24,584 base.py handle_uncaught_exception 256 Internal Server Error: /admin/login/
Traceback (most recent call last):
  File "/home/guinsly/.pyenv/versions/django1.9.3.4.3/lib/python3.4/site-packages/django/core/handlers/base.py", line 132, in get_response
    response = wrapped_callback(request, *callback_args, **callback_kwargs)
  File "/home/guinsly/.pyenv/versions/django1.9.3.4.3/lib/python3.4/site-packages/django/views/decorators/cache.py", line 57, in _wrapped_view_func
    response = view_func(request, *args, **kwargs)
  File "/home/guinsly/.pyenv/versions/django1.9.3.4.3/lib/python3.4/site-packages/django/contrib/admin/sites.py", line 400, in login
    return login(request, **defaults)
  File "/home/guinsly/.pyenv/versions/django1.9.3.4.3/lib/python3.4/site-packages/django/views/decorators/debug.py", line 76, in sensitive_post_parameters_wrapper
    return view(request, *args, **kwargs)
  File "/home/guinsly/.pyenv/versions/django1.9.3.4.3/lib/python3.4/site-packages/django/utils/decorators.py", line 110, in _wrapped_view
    response = view_func(request, *args, **kwargs)
  File "/home/guinsly/.pyenv/versions/django1.9.3.4.3/lib/python3.4/site-packages/django/views/decorators/cache.py", line 57, in _wrapped_view_func
    response = view_func(request, *args, **kwargs)
  File "/home/guinsly/.pyenv/versions/django1.9.3.4.3/lib/python3.4/site-packages/django/contrib/auth/views.py", line 57, in login
    current_site = get_current_site(request)
  File "/home/guinsly/.pyenv/versions/django1.9.3.4.3/lib/python3.4/site-packages/django/contrib/sites/shortcuts.py", line 15, in get_current_site
    return Site.objects.get_current(request)
  File "/home/guinsly/.pyenv/versions/django1.9.3.4.3/lib/python3.4/site-packages/django/contrib/sites/models.py", line 62, in get_current
    return self._get_site_by_request(request)
  File "/home/guinsly/.pyenv/versions/django1.9.3.4.3/lib/python3.4/site-packages/django/contrib/sites/models.py", line 46, in _get_site_by_request
    site = self.get(domain__iexact=host)
  File "/home/guinsly/.pyenv/versions/django1.9.3.4.3/lib/python3.4/site-packages/django/db/models/manager.py", line 127, in manager_method
    return getattr(self.get_queryset(), name)(*args, **kwargs)
  File "/home/guinsly/.pyenv/versions/django1.9.3.4.3/lib/python3.4/site-packages/django/db/models/query.py", line 334, in get
    self.model._meta.object_name
django.contrib.sites.models.DoesNotExist: Site matching query does not exist.
ERROR 2016-06-07 18:49:24,584 base.py handle_uncaught_exception 256 Internal Server Error: /admin/login/
Traceback (most recent call last):
  File "/home/guinsly/.pyenv/versions/django1.9.3.4.3/lib/python3.4/site-packages/django/core/handlers/base.py", line 132, in get_response
    response = wrapped_callback(request, *callback_args, **callback_kwargs)
  File "/home/guinsly/.pyenv/versions/django1.9.3.4.3/lib/python3.4/site-packages/django/views/decorators/cache.py", line 57, in _wrapped_view_func
    response = view_func(request, *args, **kwargs)
  File "/home/guinsly/.pyenv/versions/django1.9.3.4.3/lib/python3.4/site-packages/django/contrib/admin/sites.py", line 400, in login
    return login(request, **defaults)
  File "/home/guinsly/.pyenv/versions/django1.9.3.4.3/lib/python3.4/site-packages/django/views/decorators/debug.py", line 76, in sensitive_post_parameters_wrapper
    return view(request, *args, **kwargs)
  File "/home/guinsly/.pyenv/versions/django1.9.3.4.3/lib/python3.4/site-packages/django/utils/decorators.py", line 110, in _wrapped_view
    response = view_func(request, *args, **kwargs)
  File "/home/guinsly/.pyenv/versions/django1.9.3.4.3/lib/python3.4/site-packages/django/views/decorators/cache.py", line 57, in _wrapped_view_func
    response = view_func(request, *args, **kwargs)
  File "/home/guinsly/.pyenv/versions/django1.9.3.4.3/lib/python3.4/site-packages/django/contrib/auth/views.py", line 57, in login
    current_site = get_current_site(request)
  File "/home/guinsly/.pyenv/versions/django1.9.3.4.3/lib/python3.4/site-packages/django/contrib/sites/shortcuts.py", line 15, in get_current_site
    return Site.objects.get_current(request)
  File "/home/guinsly/.pyenv/versions/django1.9.3.4.3/lib/python3.4/site-packages/django/contrib/sites/models.py", line 62, in get_current
    return self._get_site_by_request(request)
  File "/home/guinsly/.pyenv/versions/django1.9.3.4.3/lib/python3.4/site-packages/django/contrib/sites/models.py", line 46, in _get_site_by_request
    site = self.get(domain__iexact=host)
  File "/home/guinsly/.pyenv/versions/django1.9.3.4.3/lib/python3.4/site-packages/django/db/models/manager.py", line 127, in manager_method
    return getattr(self.get_queryset(), name)(*args, **kwargs)
  File "/home/guinsly/.pyenv/versions/django1.9.3.4.3/lib/python3.4/site-packages/django/db/models/query.py", line 334, in get
    self.model._meta.object_name
django.contrib.sites.models.DoesNotExist: Site matching query does not exist.
ERROR 2016-06-07 18:51:26,638 base.py handle_uncaught_exception 256 Internal Server Error: /admin/login/
Traceback (most recent call last):
  File "/home/guinsly/.pyenv/versions/django1.9.3.4.3/lib/python3.4/site-packages/django/core/handlers/base.py", line 132, in get_response
    response = wrapped_callback(request, *callback_args, **callback_kwargs)
  File "/home/guinsly/.pyenv/versions/django1.9.3.4.3/lib/python3.4/site-packages/django/views/decorators/cache.py", line 57, in _wrapped_view_func
    response = view_func(request, *args, **kwargs)
  File "/home/guinsly/.pyenv/versions/django1.9.3.4.3/lib/python3.4/site-packages/django/contrib/admin/sites.py", line 400, in login
    return login(request, **defaults)
  File "/home/guinsly/.pyenv/versions/django1.9.3.4.3/lib/python3.4/site-packages/django/views/decorators/debug.py", line 76, in sensitive_post_parameters_wrapper
    return view(request, *args, **kwargs)
  File "/home/guinsly/.pyenv/versions/django1.9.3.4.3/lib/python3.4/site-packages/django/utils/decorators.py", line 110, in _wrapped_view
    response = view_func(request, *args, **kwargs)
  File "/home/guinsly/.pyenv/versions/django1.9.3.4.3/lib/python3.4/site-packages/django/views/decorators/cache.py", line 57, in _wrapped_view_func
    response = view_func(request, *args, **kwargs)
  File "/home/guinsly/.pyenv/versions/django1.9.3.4.3/lib/python3.4/site-packages/django/contrib/auth/views.py", line 57, in login
    current_site = get_current_site(request)
  File "/home/guinsly/.pyenv/versions/django1.9.3.4.3/lib/python3.4/site-packages/django/contrib/sites/shortcuts.py", line 15, in get_current_site
    return Site.objects.get_current(request)
  File "/home/guinsly/.pyenv/versions/django1.9.3.4.3/lib/python3.4/site-packages/django/contrib/sites/models.py", line 62, in get_current
    return self._get_site_by_request(request)
  File "/home/guinsly/.pyenv/versions/django1.9.3.4.3/lib/python3.4/site-packages/django/contrib/sites/models.py", line 46, in _get_site_by_request
    site = self.get(domain__iexact=host)
  File "/home/guinsly/.pyenv/versions/django1.9.3.4.3/lib/python3.4/site-packages/django/db/models/manager.py", line 127, in manager_method
    return getattr(self.get_queryset(), name)(*args, **kwargs)
  File "/home/guinsly/.pyenv/versions/django1.9.3.4.3/lib/python3.4/site-packages/django/db/models/query.py", line 334, in get
    self.model._meta.object_name
django.contrib.sites.models.DoesNotExist: Site matching query does not exist.
ERROR 2016-06-07 18:51:26,638 base.py handle_uncaught_exception 256 Internal Server Error: /admin/login/
Traceback (most recent call last):
  File "/home/guinsly/.pyenv/versions/django1.9.3.4.3/lib/python3.4/site-packages/django/core/handlers/base.py", line 132, in get_response
    response = wrapped_callback(request, *callback_args, **callback_kwargs)
  File "/home/guinsly/.pyenv/versions/django1.9.3.4.3/lib/python3.4/site-packages/django/views/decorators/cache.py", line 57, in _wrapped_view_func
    response = view_func(request, *args, **kwargs)
  File "/home/guinsly/.pyenv/versions/django1.9.3.4.3/lib/python3.4/site-packages/django/contrib/admin/sites.py", line 400, in login
    return login(request, **defaults)
  File "/home/guinsly/.pyenv/versions/django1.9.3.4.3/lib/python3.4/site-packages/django/views/decorators/debug.py", line 76, in sensitive_post_parameters_wrapper
    return view(request, *args, **kwargs)
  File "/home/guinsly/.pyenv/versions/django1.9.3.4.3/lib/python3.4/site-packages/django/utils/decorators.py", line 110, in _wrapped_view
    response = view_func(request, *args, **kwargs)
  File "/home/guinsly/.pyenv/versions/django1.9.3.4.3/lib/python3.4/site-packages/django/views/decorators/cache.py", line 57, in _wrapped_view_func
    response = view_func(request, *args, **kwargs)
  File "/home/guinsly/.pyenv/versions/django1.9.3.4.3/lib/python3.4/site-packages/django/contrib/auth/views.py", line 57, in login
    current_site = get_current_site(request)
  File "/home/guinsly/.pyenv/versions/django1.9.3.4.3/lib/python3.4/site-packages/django/contrib/sites/shortcuts.py", line 15, in get_current_site
    return Site.objects.get_current(request)
  File "/home/guinsly/.pyenv/versions/django1.9.3.4.3/lib/python3.4/site-packages/django/contrib/sites/models.py", line 62, in get_current
    return self._get_site_by_request(request)
  File "/home/guinsly/.pyenv/versions/django1.9.3.4.3/lib/python3.4/site-packages/django/contrib/sites/models.py", line 46, in _get_site_by_request
    site = self.get(domain__iexact=host)
  File "/home/guinsly/.pyenv/versions/django1.9.3.4.3/lib/python3.4/site-packages/django/db/models/manager.py", line 127, in manager_method
    return getattr(self.get_queryset(), name)(*args, **kwargs)
  File "/home/guinsly/.pyenv/versions/django1.9.3.4.3/lib/python3.4/site-packages/django/db/models/query.py", line 334, in get
    self.model._meta.object_name
django.contrib.sites.models.DoesNotExist: Site matching query does not exist.
ERROR 2016-06-07 18:51:26,638 base.py handle_uncaught_exception 256 Internal Server Error: /admin/login/
Traceback (most recent call last):
  File "/home/guinsly/.pyenv/versions/django1.9.3.4.3/lib/python3.4/site-packages/django/core/handlers/base.py", line 132, in get_response
    response = wrapped_callback(request, *callback_args, **callback_kwargs)
  File "/home/guinsly/.pyenv/versions/django1.9.3.4.3/lib/python3.4/site-packages/django/views/decorators/cache.py", line 57, in _wrapped_view_func
    response = view_func(request, *args, **kwargs)
  File "/home/guinsly/.pyenv/versions/django1.9.3.4.3/lib/python3.4/site-packages/django/contrib/admin/sites.py", line 400, in login
    return login(request, **defaults)
  File "/home/guinsly/.pyenv/versions/django1.9.3.4.3/lib/python3.4/site-packages/django/views/decorators/debug.py", line 76, in sensitive_post_parameters_wrapper
    return view(request, *args, **kwargs)
  File "/home/guinsly/.pyenv/versions/django1.9.3.4.3/lib/python3.4/site-packages/django/utils/decorators.py", line 110, in _wrapped_view
    response = view_func(request, *args, **kwargs)
  File "/home/guinsly/.pyenv/versions/django1.9.3.4.3/lib/python3.4/site-packages/django/views/decorators/cache.py", line 57, in _wrapped_view_func
    response = view_func(request, *args, **kwargs)
  File "/home/guinsly/.pyenv/versions/django1.9.3.4.3/lib/python3.4/site-packages/django/contrib/auth/views.py", line 57, in login
    current_site = get_current_site(request)
  File "/home/guinsly/.pyenv/versions/django1.9.3.4.3/lib/python3.4/site-packages/django/contrib/sites/shortcuts.py", line 15, in get_current_site
    return Site.objects.get_current(request)
  File "/home/guinsly/.pyenv/versions/django1.9.3.4.3/lib/python3.4/site-packages/django/contrib/sites/models.py", line 62, in get_current
    return self._get_site_by_request(request)
  File "/home/guinsly/.pyenv/versions/django1.9.3.4.3/lib/python3.4/site-packages/django/contrib/sites/models.py", line 46, in _get_site_by_request
    site = self.get(domain__iexact=host)
  File "/home/guinsly/.pyenv/versions/django1.9.3.4.3/lib/python3.4/site-packages/django/db/models/manager.py", line 127, in manager_method
    return getattr(self.get_queryset(), name)(*args, **kwargs)
  File "/home/guinsly/.pyenv/versions/django1.9.3.4.3/lib/python3.4/site-packages/django/db/models/query.py", line 334, in get
    self.model._meta.object_name
django.contrib.sites.models.DoesNotExist: Site matching query does not exist.
ERROR 2016-06-07 18:51:51,996 base.py handle_uncaught_exception 256 Internal Server Error: /admin/login/
Traceback (most recent call last):
  File "/home/guinsly/.pyenv/versions/django1.9.3.4.3/lib/python3.4/site-packages/django/core/handlers/base.py", line 132, in get_response
    response = wrapped_callback(request, *callback_args, **callback_kwargs)
  File "/home/guinsly/.pyenv/versions/django1.9.3.4.3/lib/python3.4/site-packages/django/views/decorators/cache.py", line 57, in _wrapped_view_func
    response = view_func(request, *args, **kwargs)
  File "/home/guinsly/.pyenv/versions/django1.9.3.4.3/lib/python3.4/site-packages/django/contrib/admin/sites.py", line 400, in login
    return login(request, **defaults)
  File "/home/guinsly/.pyenv/versions/django1.9.3.4.3/lib/python3.4/site-packages/django/views/decorators/debug.py", line 76, in sensitive_post_parameters_wrapper
    return view(request, *args, **kwargs)
  File "/home/guinsly/.pyenv/versions/django1.9.3.4.3/lib/python3.4/site-packages/django/utils/decorators.py", line 110, in _wrapped_view
    response = view_func(request, *args, **kwargs)
  File "/home/guinsly/.pyenv/versions/django1.9.3.4.3/lib/python3.4/site-packages/django/views/decorators/cache.py", line 57, in _wrapped_view_func
    response = view_func(request, *args, **kwargs)
  File "/home/guinsly/.pyenv/versions/django1.9.3.4.3/lib/python3.4/site-packages/django/contrib/auth/views.py", line 57, in login
    current_site = get_current_site(request)
  File "/home/guinsly/.pyenv/versions/django1.9.3.4.3/lib/python3.4/site-packages/django/contrib/sites/shortcuts.py", line 15, in get_current_site
    return Site.objects.get_current(request)
  File "/home/guinsly/.pyenv/versions/django1.9.3.4.3/lib/python3.4/site-packages/django/contrib/sites/models.py", line 62, in get_current
    return self._get_site_by_request(request)
  File "/home/guinsly/.pyenv/versions/django1.9.3.4.3/lib/python3.4/site-packages/django/contrib/sites/models.py", line 46, in _get_site_by_request
    site = self.get(domain__iexact=host)
  File "/home/guinsly/.pyenv/versions/django1.9.3.4.3/lib/python3.4/site-packages/django/db/models/manager.py", line 127, in manager_method
    return getattr(self.get_queryset(), name)(*args, **kwargs)
  File "/home/guinsly/.pyenv/versions/django1.9.3.4.3/lib/python3.4/site-packages/django/db/models/query.py", line 334, in get
    self.model._meta.object_name
django.contrib.sites.models.DoesNotExist: Site matching query does not exist.
ERROR 2016-06-07 18:51:51,996 base.py handle_uncaught_exception 256 Internal Server Error: /admin/login/
Traceback (most recent call last):
  File "/home/guinsly/.pyenv/versions/django1.9.3.4.3/lib/python3.4/site-packages/django/core/handlers/base.py", line 132, in get_response
    response = wrapped_callback(request, *callback_args, **callback_kwargs)
  File "/home/guinsly/.pyenv/versions/django1.9.3.4.3/lib/python3.4/site-packages/django/views/decorators/cache.py", line 57, in _wrapped_view_func
    response = view_func(request, *args, **kwargs)
  File "/home/guinsly/.pyenv/versions/django1.9.3.4.3/lib/python3.4/site-packages/django/contrib/admin/sites.py", line 400, in login
    return login(request, **defaults)
  File "/home/guinsly/.pyenv/versions/django1.9.3.4.3/lib/python3.4/site-packages/django/views/decorators/debug.py", line 76, in sensitive_post_parameters_wrapper
    return view(request, *args, **kwargs)
  File "/home/guinsly/.pyenv/versions/django1.9.3.4.3/lib/python3.4/site-packages/django/utils/decorators.py", line 110, in _wrapped_view
    response = view_func(request, *args, **kwargs)
  File "/home/guinsly/.pyenv/versions/django1.9.3.4.3/lib/python3.4/site-packages/django/views/decorators/cache.py", line 57, in _wrapped_view_func
    response = view_func(request, *args, **kwargs)
  File "/home/guinsly/.pyenv/versions/django1.9.3.4.3/lib/python3.4/site-packages/django/contrib/auth/views.py", line 57, in login
    current_site = get_current_site(request)
  File "/home/guinsly/.pyenv/versions/django1.9.3.4.3/lib/python3.4/site-packages/django/contrib/sites/shortcuts.py", line 15, in get_current_site
    return Site.objects.get_current(request)
  File "/home/guinsly/.pyenv/versions/django1.9.3.4.3/lib/python3.4/site-packages/django/contrib/sites/models.py", line 62, in get_current
    return self._get_site_by_request(request)
  File "/home/guinsly/.pyenv/versions/django1.9.3.4.3/lib/python3.4/site-packages/django/contrib/sites/models.py", line 46, in _get_site_by_request
    site = self.get(domain__iexact=host)
  File "/home/guinsly/.pyenv/versions/django1.9.3.4.3/lib/python3.4/site-packages/django/db/models/manager.py", line 127, in manager_method
    return getattr(self.get_queryset(), name)(*args, **kwargs)
  File "/home/guinsly/.pyenv/versions/django1.9.3.4.3/lib/python3.4/site-packages/django/db/models/query.py", line 334, in get
    self.model._meta.object_name
django.contrib.sites.models.DoesNotExist: Site matching query does not exist.
ERROR 2016-06-07 18:51:51,996 base.py handle_uncaught_exception 256 Internal Server Error: /admin/login/
Traceback (most recent call last):
  File "/home/guinsly/.pyenv/versions/django1.9.3.4.3/lib/python3.4/site-packages/django/core/handlers/base.py", line 132, in get_response
    response = wrapped_callback(request, *callback_args, **callback_kwargs)
  File "/home/guinsly/.pyenv/versions/django1.9.3.4.3/lib/python3.4/site-packages/django/views/decorators/cache.py", line 57, in _wrapped_view_func
    response = view_func(request, *args, **kwargs)
  File "/home/guinsly/.pyenv/versions/django1.9.3.4.3/lib/python3.4/site-packages/django/contrib/admin/sites.py", line 400, in login
    return login(request, **defaults)
  File "/home/guinsly/.pyenv/versions/django1.9.3.4.3/lib/python3.4/site-packages/django/views/decorators/debug.py", line 76, in sensitive_post_parameters_wrapper
    return view(request, *args, **kwargs)
  File "/home/guinsly/.pyenv/versions/django1.9.3.4.3/lib/python3.4/site-packages/django/utils/decorators.py", line 110, in _wrapped_view
    response = view_func(request, *args, **kwargs)
  File "/home/guinsly/.pyenv/versions/django1.9.3.4.3/lib/python3.4/site-packages/django/views/decorators/cache.py", line 57, in _wrapped_view_func
    response = view_func(request, *args, **kwargs)
  File "/home/guinsly/.pyenv/versions/django1.9.3.4.3/lib/python3.4/site-packages/django/contrib/auth/views.py", line 57, in login
    current_site = get_current_site(request)
  File "/home/guinsly/.pyenv/versions/django1.9.3.4.3/lib/python3.4/site-packages/django/contrib/sites/shortcuts.py", line 15, in get_current_site
    return Site.objects.get_current(request)
  File "/home/guinsly/.pyenv/versions/django1.9.3.4.3/lib/python3.4/site-packages/django/contrib/sites/models.py", line 62, in get_current
    return self._get_site_by_request(request)
  File "/home/guinsly/.pyenv/versions/django1.9.3.4.3/lib/python3.4/site-packages/django/contrib/sites/models.py", line 46, in _get_site_by_request
    site = self.get(domain__iexact=host)
  File "/home/guinsly/.pyenv/versions/django1.9.3.4.3/lib/python3.4/site-packages/django/db/models/manager.py", line 127, in manager_method
    return getattr(self.get_queryset(), name)(*args, **kwargs)
  File "/home/guinsly/.pyenv/versions/django1.9.3.4.3/lib/python3.4/site-packages/django/db/models/query.py", line 334, in get
    self.model._meta.object_name
django.contrib.sites.models.DoesNotExist: Site matching query does not exist.
ERROR 2016-06-07 18:51:59,166 base.py handle_uncaught_exception 256 Internal Server Error: /admin/login/
Traceback (most recent call last):
  File "/home/guinsly/.pyenv/versions/django1.9.3.4.3/lib/python3.4/site-packages/django/core/handlers/base.py", line 132, in get_response
    response = wrapped_callback(request, *callback_args, **callback_kwargs)
  File "/home/guinsly/.pyenv/versions/django1.9.3.4.3/lib/python3.4/site-packages/django/views/decorators/cache.py", line 57, in _wrapped_view_func
    response = view_func(request, *args, **kwargs)
  File "/home/guinsly/.pyenv/versions/django1.9.3.4.3/lib/python3.4/site-packages/django/contrib/admin/sites.py", line 400, in login
    return login(request, **defaults)
  File "/home/guinsly/.pyenv/versions/django1.9.3.4.3/lib/python3.4/site-packages/django/views/decorators/debug.py", line 76, in sensitive_post_parameters_wrapper
    return view(request, *args, **kwargs)
  File "/home/guinsly/.pyenv/versions/django1.9.3.4.3/lib/python3.4/site-packages/django/utils/decorators.py", line 110, in _wrapped_view
    response = view_func(request, *args, **kwargs)
  File "/home/guinsly/.pyenv/versions/django1.9.3.4.3/lib/python3.4/site-packages/django/views/decorators/cache.py", line 57, in _wrapped_view_func
    response = view_func(request, *args, **kwargs)
  File "/home/guinsly/.pyenv/versions/django1.9.3.4.3/lib/python3.4/site-packages/django/contrib/auth/views.py", line 57, in login
    current_site = get_current_site(request)
  File "/home/guinsly/.pyenv/versions/django1.9.3.4.3/lib/python3.4/site-packages/django/contrib/sites/shortcuts.py", line 15, in get_current_site
    return Site.objects.get_current(request)
  File "/home/guinsly/.pyenv/versions/django1.9.3.4.3/lib/python3.4/site-packages/django/contrib/sites/models.py", line 62, in get_current
    return self._get_site_by_request(request)
  File "/home/guinsly/.pyenv/versions/django1.9.3.4.3/lib/python3.4/site-packages/django/contrib/sites/models.py", line 46, in _get_site_by_request
    site = self.get(domain__iexact=host)
  File "/home/guinsly/.pyenv/versions/django1.9.3.4.3/lib/python3.4/site-packages/django/db/models/manager.py", line 127, in manager_method
    return getattr(self.get_queryset(), name)(*args, **kwargs)
  File "/home/guinsly/.pyenv/versions/django1.9.3.4.3/lib/python3.4/site-packages/django/db/models/query.py", line 334, in get
    self.model._meta.object_name
django.contrib.sites.models.DoesNotExist: Site matching query does not exist.
ERROR 2016-06-07 18:51:59,166 base.py handle_uncaught_exception 256 Internal Server Error: /admin/login/
Traceback (most recent call last):
  File "/home/guinsly/.pyenv/versions/django1.9.3.4.3/lib/python3.4/site-packages/django/core/handlers/base.py", line 132, in get_response
    response = wrapped_callback(request, *callback_args, **callback_kwargs)
  File "/home/guinsly/.pyenv/versions/django1.9.3.4.3/lib/python3.4/site-packages/django/views/decorators/cache.py", line 57, in _wrapped_view_func
    response = view_func(request, *args, **kwargs)
  File "/home/guinsly/.pyenv/versions/django1.9.3.4.3/lib/python3.4/site-packages/django/contrib/admin/sites.py", line 400, in login
    return login(request, **defaults)
  File "/home/guinsly/.pyenv/versions/django1.9.3.4.3/lib/python3.4/site-packages/django/views/decorators/debug.py", line 76, in sensitive_post_parameters_wrapper
    return view(request, *args, **kwargs)
  File "/home/guinsly/.pyenv/versions/django1.9.3.4.3/lib/python3.4/site-packages/django/utils/decorators.py", line 110, in _wrapped_view
    response = view_func(request, *args, **kwargs)
  File "/home/guinsly/.pyenv/versions/django1.9.3.4.3/lib/python3.4/site-packages/django/views/decorators/cache.py", line 57, in _wrapped_view_func
    response = view_func(request, *args, **kwargs)
  File "/home/guinsly/.pyenv/versions/django1.9.3.4.3/lib/python3.4/site-packages/django/contrib/auth/views.py", line 57, in login
    current_site = get_current_site(request)
  File "/home/guinsly/.pyenv/versions/django1.9.3.4.3/lib/python3.4/site-packages/django/contrib/sites/shortcuts.py", line 15, in get_current_site
    return Site.objects.get_current(request)
  File "/home/guinsly/.pyenv/versions/django1.9.3.4.3/lib/python3.4/site-packages/django/contrib/sites/models.py", line 62, in get_current
    return self._get_site_by_request(request)
  File "/home/guinsly/.pyenv/versions/django1.9.3.4.3/lib/python3.4/site-packages/django/contrib/sites/models.py", line 46, in _get_site_by_request
    site = self.get(domain__iexact=host)
  File "/home/guinsly/.pyenv/versions/django1.9.3.4.3/lib/python3.4/site-packages/django/db/models/manager.py", line 127, in manager_method
    return getattr(self.get_queryset(), name)(*args, **kwargs)
  File "/home/guinsly/.pyenv/versions/django1.9.3.4.3/lib/python3.4/site-packages/django/db/models/query.py", line 334, in get
    self.model._meta.object_name
django.contrib.sites.models.DoesNotExist: Site matching query does not exist.
ERROR 2016-06-07 18:51:59,166 base.py handle_uncaught_exception 256 Internal Server Error: /admin/login/
Traceback (most recent call last):
  File "/home/guinsly/.pyenv/versions/django1.9.3.4.3/lib/python3.4/site-packages/django/core/handlers/base.py", line 132, in get_response
    response = wrapped_callback(request, *callback_args, **callback_kwargs)
  File "/home/guinsly/.pyenv/versions/django1.9.3.4.3/lib/python3.4/site-packages/django/views/decorators/cache.py", line 57, in _wrapped_view_func
    response = view_func(request, *args, **kwargs)
  File "/home/guinsly/.pyenv/versions/django1.9.3.4.3/lib/python3.4/site-packages/django/contrib/admin/sites.py", line 400, in login
    return login(request, **defaults)
  File "/home/guinsly/.pyenv/versions/django1.9.3.4.3/lib/python3.4/site-packages/django/views/decorators/debug.py", line 76, in sensitive_post_parameters_wrapper
    return view(request, *args, **kwargs)
  File "/home/guinsly/.pyenv/versions/django1.9.3.4.3/lib/python3.4/site-packages/django/utils/decorators.py", line 110, in _wrapped_view
    response = view_func(request, *args, **kwargs)
  File "/home/guinsly/.pyenv/versions/django1.9.3.4.3/lib/python3.4/site-packages/django/views/decorators/cache.py", line 57, in _wrapped_view_func
    response = view_func(request, *args, **kwargs)
  File "/home/guinsly/.pyenv/versions/django1.9.3.4.3/lib/python3.4/site-packages/django/contrib/auth/views.py", line 57, in login
    current_site = get_current_site(request)
  File "/home/guinsly/.pyenv/versions/django1.9.3.4.3/lib/python3.4/site-packages/django/contrib/sites/shortcuts.py", line 15, in get_current_site
    return Site.objects.get_current(request)
  File "/home/guinsly/.pyenv/versions/django1.9.3.4.3/lib/python3.4/site-packages/django/contrib/sites/models.py", line 62, in get_current
    return self._get_site_by_request(request)
  File "/home/guinsly/.pyenv/versions/django1.9.3.4.3/lib/python3.4/site-packages/django/contrib/sites/models.py", line 46, in _get_site_by_request
    site = self.get(domain__iexact=host)
  File "/home/guinsly/.pyenv/versions/django1.9.3.4.3/lib/python3.4/site-packages/django/db/models/manager.py", line 127, in manager_method
    return getattr(self.get_queryset(), name)(*args, **kwargs)
  File "/home/guinsly/.pyenv/versions/django1.9.3.4.3/lib/python3.4/site-packages/django/db/models/query.py", line 334, in get
    self.model._meta.object_name
django.contrib.sites.models.DoesNotExist: Site matching query does not exist.
ERROR 2016-06-07 18:58:07,666 base.py handle_uncaught_exception 256 Internal Server Error: /admin/websites/website404/add/
Traceback (most recent call last):
  File "/home/guinsly/.pyenv/versions/django1.9.3.4.3/lib/python3.4/site-packages/django/core/handlers/base.py", line 132, in get_response
    response = wrapped_callback(request, *callback_args, **callback_kwargs)
  File "/home/guinsly/.pyenv/versions/django1.9.3.4.3/lib/python3.4/site-packages/django/contrib/admin/options.py", line 618, in wrapper
    return self.admin_site.admin_view(view)(*args, **kwargs)
  File "/home/guinsly/.pyenv/versions/django1.9.3.4.3/lib/python3.4/site-packages/django/utils/decorators.py", line 110, in _wrapped_view
    response = view_func(request, *args, **kwargs)
  File "/home/guinsly/.pyenv/versions/django1.9.3.4.3/lib/python3.4/site-packages/django/views/decorators/cache.py", line 57, in _wrapped_view_func
    response = view_func(request, *args, **kwargs)
  File "/home/guinsly/.pyenv/versions/django1.9.3.4.3/lib/python3.4/site-packages/django/contrib/admin/sites.py", line 233, in inner
    return view(request, *args, **kwargs)
  File "/home/guinsly/.pyenv/versions/django1.9.3.4.3/lib/python3.4/site-packages/django/contrib/admin/options.py", line 1518, in add_view
    return self.changeform_view(request, None, form_url, extra_context)
  File "/home/guinsly/.pyenv/versions/django1.9.3.4.3/lib/python3.4/site-packages/django/utils/decorators.py", line 34, in _wrapper
    return bound_func(*args, **kwargs)
  File "/home/guinsly/.pyenv/versions/django1.9.3.4.3/lib/python3.4/site-packages/django/utils/decorators.py", line 110, in _wrapped_view
    response = view_func(request, *args, **kwargs)
  File "/home/guinsly/.pyenv/versions/django1.9.3.4.3/lib/python3.4/site-packages/django/utils/decorators.py", line 30, in bound_func
    return func.__get__(self, type(self))(*args2, **kwargs2)
  File "/home/guinsly/.pyenv/versions/3.4.4/lib/python3.4/contextlib.py", line 30, in inner
    return func(*args, **kwds)
  File "/home/guinsly/.pyenv/versions/django1.9.3.4.3/lib/python3.4/site-packages/django/contrib/admin/options.py", line 1469, in changeform_view
    self.save_model(request, new_object, form, not add)
  File "/home/guinsly/.pyenv/versions/django1.9.3.4.3/lib/python3.4/site-packages/django/contrib/admin/options.py", line 1080, in save_model
    obj.save()
  File "/home/guinsly/.pyenv/versions/django1.9.3.4.3/lib/python3.4/site-packages/django/db/models/base.py", line 734, in save
    force_update=force_update, update_fields=update_fields)
  File "/home/guinsly/.pyenv/versions/django1.9.3.4.3/lib/python3.4/site-packages/django/db/models/base.py", line 771, in save_base
    update_fields=update_fields, raw=raw, using=using)
  File "/home/guinsly/.pyenv/versions/django1.9.3.4.3/lib/python3.4/site-packages/django/dispatch/dispatcher.py", line 189, in send
    response = receiver(signal=self, sender=sender, **named)
  File "/home/guinsly/.pyenv/versions/django1.9.3.4.3/lib/python3.4/site-packages/imagekit/specs/sourcegroups.py", line 33, in receiver
    fn(self, sender=sender, **kwargs)
  File "/home/guinsly/.pyenv/versions/django1.9.3.4.3/lib/python3.4/site-packages/imagekit/specs/sourcegroups.py", line 94, in post_save_receiver
    new_hashes = self.update_source_hashes(instance)
  File "/home/guinsly/.pyenv/versions/django1.9.3.4.3/lib/python3.4/site-packages/imagekit/specs/sourcegroups.py", line 77, in update_source_hashes
    for attname in self.get_source_fields(instance))
  File "/home/guinsly/.pyenv/versions/django1.9.3.4.3/lib/python3.4/site-packages/imagekit/specs/sourcegroups.py", line 77, in <genexpr>
    for attname in self.get_source_fields(instance))
AttributeError: 'website404' object has no attribute 'avatar'
ERROR 2016-06-07 18:58:07,666 base.py handle_uncaught_exception 256 Internal Server Error: /admin/websites/website404/add/
Traceback (most recent call last):
  File "/home/guinsly/.pyenv/versions/django1.9.3.4.3/lib/python3.4/site-packages/django/core/handlers/base.py", line 132, in get_response
    response = wrapped_callback(request, *callback_args, **callback_kwargs)
  File "/home/guinsly/.pyenv/versions/django1.9.3.4.3/lib/python3.4/site-packages/django/contrib/admin/options.py", line 618, in wrapper
    return self.admin_site.admin_view(view)(*args, **kwargs)
  File "/home/guinsly/.pyenv/versions/django1.9.3.4.3/lib/python3.4/site-packages/django/utils/decorators.py", line 110, in _wrapped_view
    response = view_func(request, *args, **kwargs)
  File "/home/guinsly/.pyenv/versions/django1.9.3.4.3/lib/python3.4/site-packages/django/views/decorators/cache.py", line 57, in _wrapped_view_func
    response = view_func(request, *args, **kwargs)
  File "/home/guinsly/.pyenv/versions/django1.9.3.4.3/lib/python3.4/site-packages/django/contrib/admin/sites.py", line 233, in inner
    return view(request, *args, **kwargs)
  File "/home/guinsly/.pyenv/versions/django1.9.3.4.3/lib/python3.4/site-packages/django/contrib/admin/options.py", line 1518, in add_view
    return self.changeform_view(request, None, form_url, extra_context)
  File "/home/guinsly/.pyenv/versions/django1.9.3.4.3/lib/python3.4/site-packages/django/utils/decorators.py", line 34, in _wrapper
    return bound_func(*args, **kwargs)
  File "/home/guinsly/.pyenv/versions/django1.9.3.4.3/lib/python3.4/site-packages/django/utils/decorators.py", line 110, in _wrapped_view
    response = view_func(request, *args, **kwargs)
  File "/home/guinsly/.pyenv/versions/django1.9.3.4.3/lib/python3.4/site-packages/django/utils/decorators.py", line 30, in bound_func
    return func.__get__(self, type(self))(*args2, **kwargs2)
  File "/home/guinsly/.pyenv/versions/3.4.4/lib/python3.4/contextlib.py", line 30, in inner
    return func(*args, **kwds)
  File "/home/guinsly/.pyenv/versions/django1.9.3.4.3/lib/python3.4/site-packages/django/contrib/admin/options.py", line 1469, in changeform_view
    self.save_model(request, new_object, form, not add)
  File "/home/guinsly/.pyenv/versions/django1.9.3.4.3/lib/python3.4/site-packages/django/contrib/admin/options.py", line 1080, in save_model
    obj.save()
  File "/home/guinsly/.pyenv/versions/django1.9.3.4.3/lib/python3.4/site-packages/django/db/models/base.py", line 734, in save
    force_update=force_update, update_fields=update_fields)
  File "/home/guinsly/.pyenv/versions/django1.9.3.4.3/lib/python3.4/site-packages/django/db/models/base.py", line 771, in save_base
    update_fields=update_fields, raw=raw, using=using)
  File "/home/guinsly/.pyenv/versions/django1.9.3.4.3/lib/python3.4/site-packages/django/dispatch/dispatcher.py", line 189, in send
    response = receiver(signal=self, sender=sender, **named)
  File "/home/guinsly/.pyenv/versions/django1.9.3.4.3/lib/python3.4/site-packages/imagekit/specs/sourcegroups.py", line 33, in receiver
    fn(self, sender=sender, **kwargs)
  File "/home/guinsly/.pyenv/versions/django1.9.3.4.3/lib/python3.4/site-packages/imagekit/specs/sourcegroups.py", line 94, in post_save_receiver
    new_hashes = self.update_source_hashes(instance)
  File "/home/guinsly/.pyenv/versions/django1.9.3.4.3/lib/python3.4/site-packages/imagekit/specs/sourcegroups.py", line 77, in update_source_hashes
    for attname in self.get_source_fields(instance))
  File "/home/guinsly/.pyenv/versions/django1.9.3.4.3/lib/python3.4/site-packages/imagekit/specs/sourcegroups.py", line 77, in <genexpr>
    for attname in self.get_source_fields(instance))
AttributeError: 'website404' object has no attribute 'avatar'
ERROR 2016-06-07 18:58:07,666 base.py handle_uncaught_exception 256 Internal Server Error: /admin/websites/website404/add/
Traceback (most recent call last):
  File "/home/guinsly/.pyenv/versions/django1.9.3.4.3/lib/python3.4/site-packages/django/core/handlers/base.py", line 132, in get_response
    response = wrapped_callback(request, *callback_args, **callback_kwargs)
  File "/home/guinsly/.pyenv/versions/django1.9.3.4.3/lib/python3.4/site-packages/django/contrib/admin/options.py", line 618, in wrapper
    return self.admin_site.admin_view(view)(*args, **kwargs)
  File "/home/guinsly/.pyenv/versions/django1.9.3.4.3/lib/python3.4/site-packages/django/utils/decorators.py", line 110, in _wrapped_view
    response = view_func(request, *args, **kwargs)
  File "/home/guinsly/.pyenv/versions/django1.9.3.4.3/lib/python3.4/site-packages/django/views/decorators/cache.py", line 57, in _wrapped_view_func
    response = view_func(request, *args, **kwargs)
  File "/home/guinsly/.pyenv/versions/django1.9.3.4.3/lib/python3.4/site-packages/django/contrib/admin/sites.py", line 233, in inner
    return view(request, *args, **kwargs)
  File "/home/guinsly/.pyenv/versions/django1.9.3.4.3/lib/python3.4/site-packages/django/contrib/admin/options.py", line 1518, in add_view
    return self.changeform_view(request, None, form_url, extra_context)
  File "/home/guinsly/.pyenv/versions/django1.9.3.4.3/lib/python3.4/site-packages/django/utils/decorators.py", line 34, in _wrapper
    return bound_func(*args, **kwargs)
  File "/home/guinsly/.pyenv/versions/django1.9.3.4.3/lib/python3.4/site-packages/django/utils/decorators.py", line 110, in _wrapped_view
    response = view_func(request, *args, **kwargs)
  File "/home/guinsly/.pyenv/versions/django1.9.3.4.3/lib/python3.4/site-packages/django/utils/decorators.py", line 30, in bound_func
    return func.__get__(self, type(self))(*args2, **kwargs2)
  File "/home/guinsly/.pyenv/versions/3.4.4/lib/python3.4/contextlib.py", line 30, in inner
    return func(*args, **kwds)
  File "/home/guinsly/.pyenv/versions/django1.9.3.4.3/lib/python3.4/site-packages/django/contrib/admin/options.py", line 1469, in changeform_view
    self.save_model(request, new_object, form, not add)
  File "/home/guinsly/.pyenv/versions/django1.9.3.4.3/lib/python3.4/site-packages/django/contrib/admin/options.py", line 1080, in save_model
    obj.save()
  File "/home/guinsly/.pyenv/versions/django1.9.3.4.3/lib/python3.4/site-packages/django/db/models/base.py", line 734, in save
    force_update=force_update, update_fields=update_fields)
  File "/home/guinsly/.pyenv/versions/django1.9.3.4.3/lib/python3.4/site-packages/django/db/models/base.py", line 771, in save_base
    update_fields=update_fields, raw=raw, using=using)
  File "/home/guinsly/.pyenv/versions/django1.9.3.4.3/lib/python3.4/site-packages/django/dispatch/dispatcher.py", line 189, in send
    response = receiver(signal=self, sender=sender, **named)
  File "/home/guinsly/.pyenv/versions/django1.9.3.4.3/lib/python3.4/site-packages/imagekit/specs/sourcegroups.py", line 33, in receiver
    fn(self, sender=sender, **kwargs)
  File "/home/guinsly/.pyenv/versions/django1.9.3.4.3/lib/python3.4/site-packages/imagekit/specs/sourcegroups.py", line 94, in post_save_receiver
    new_hashes = self.update_source_hashes(instance)
  File "/home/guinsly/.pyenv/versions/django1.9.3.4.3/lib/python3.4/site-packages/imagekit/specs/sourcegroups.py", line 77, in update_source_hashes
    for attname in self.get_source_fields(instance))
  File "/home/guinsly/.pyenv/versions/django1.9.3.4.3/lib/python3.4/site-packages/imagekit/specs/sourcegroups.py", line 77, in <genexpr>
    for attname in self.get_source_fields(instance))
AttributeError: 'website404' object has no attribute 'avatar'
ERROR 2016-06-07 19:15:59,953 base.py handle_uncaught_exception 256 Internal Server Error: /
Traceback (most recent call last):
  File "/home/guinsly/.pyenv/versions/django1.9.3.4.3/lib/python3.4/site-packages/django/core/handlers/base.py", line 164, in get_response
    response = response.render()
  File "/home/guinsly/.pyenv/versions/django1.9.3.4.3/lib/python3.4/site-packages/django/template/response.py", line 158, in render
    self.content = self.rendered_content
  File "/home/guinsly/.pyenv/versions/django1.9.3.4.3/lib/python3.4/site-packages/django/template/response.py", line 133, in rendered_content
    template = self._resolve_template(self.template_name)
  File "/home/guinsly/.pyenv/versions/django1.9.3.4.3/lib/python3.4/site-packages/django/template/response.py", line 88, in _resolve_template
    new_template = self.resolve_template(template)
  File "/home/guinsly/.pyenv/versions/django1.9.3.4.3/lib/python3.4/site-packages/django/template/response.py", line 78, in resolve_template
    return loader.select_template(template, using=self.using)
  File "/home/guinsly/.pyenv/versions/django1.9.3.4.3/lib/python3.4/site-packages/django/template/loader.py", line 76, in select_template
    raise TemplateDoesNotExist(', '.join(template_name_list))
django.template.base.TemplateDoesNotExist: websites/website404_list.html
ERROR 2016-06-07 19:15:59,953 base.py handle_uncaught_exception 256 Internal Server Error: /
Traceback (most recent call last):
  File "/home/guinsly/.pyenv/versions/django1.9.3.4.3/lib/python3.4/site-packages/django/core/handlers/base.py", line 164, in get_response
    response = response.render()
  File "/home/guinsly/.pyenv/versions/django1.9.3.4.3/lib/python3.4/site-packages/django/template/response.py", line 158, in render
    self.content = self.rendered_content
  File "/home/guinsly/.pyenv/versions/django1.9.3.4.3/lib/python3.4/site-packages/django/template/response.py", line 133, in rendered_content
    template = self._resolve_template(self.template_name)
  File "/home/guinsly/.pyenv/versions/django1.9.3.4.3/lib/python3.4/site-packages/django/template/response.py", line 88, in _resolve_template
    new_template = self.resolve_template(template)
  File "/home/guinsly/.pyenv/versions/django1.9.3.4.3/lib/python3.4/site-packages/django/template/response.py", line 78, in resolve_template
    return loader.select_template(template, using=self.using)
  File "/home/guinsly/.pyenv/versions/django1.9.3.4.3/lib/python3.4/site-packages/django/template/loader.py", line 76, in select_template
    raise TemplateDoesNotExist(', '.join(template_name_list))
django.template.base.TemplateDoesNotExist: websites/website404_list.html
ERROR 2016-06-07 19:15:59,953 base.py handle_uncaught_exception 256 Internal Server Error: /
Traceback (most recent call last):
  File "/home/guinsly/.pyenv/versions/django1.9.3.4.3/lib/python3.4/site-packages/django/core/handlers/base.py", line 164, in get_response
    response = response.render()
  File "/home/guinsly/.pyenv/versions/django1.9.3.4.3/lib/python3.4/site-packages/django/template/response.py", line 158, in render
    self.content = self.rendered_content
  File "/home/guinsly/.pyenv/versions/django1.9.3.4.3/lib/python3.4/site-packages/django/template/response.py", line 133, in rendered_content
    template = self._resolve_template(self.template_name)
  File "/home/guinsly/.pyenv/versions/django1.9.3.4.3/lib/python3.4/site-packages/django/template/response.py", line 88, in _resolve_template
    new_template = self.resolve_template(template)
  File "/home/guinsly/.pyenv/versions/django1.9.3.4.3/lib/python3.4/site-packages/django/template/response.py", line 78, in resolve_template
    return loader.select_template(template, using=self.using)
  File "/home/guinsly/.pyenv/versions/django1.9.3.4.3/lib/python3.4/site-packages/django/template/loader.py", line 76, in select_template
    raise TemplateDoesNotExist(', '.join(template_name_list))
django.template.base.TemplateDoesNotExist: websites/website404_list.html
